<?xml version="1.0" ?>
<!-- =================================================================================== -->
<!-- |    This document was autogenerated by xacro from sobit_education.urdf.xacro     | -->
<!-- |    EDITING THIS FILE BY HAND IS NOT RECOMMENDED                                 | -->
<!-- =================================================================================== -->
<robot name="sobit_education" xmlns:controller="http://playerstage.sourceforge.net/gazebo/xmlschema/#controller" xmlns:interface="http://playerstage.sourceforge.net/gazebo/xmlschema/#interface" xmlns:sensor="http://playerstage.sourceforge.net/gazebo/xmlschema/#sensor">
  <material name="wheel">
    <color rgba="0.2 0.2 0.2 1.0"/>
  </material>
  <material name="black">
    <color rgba="0.1 0.1 0.1 1.0"/>
  </material>
  <material name="red">
    <color rgba="1.0 0.0 0.0 1.0"/>
  </material>
  <material name="green">
    <color rgba="0.0 1.0 0.0 1.0"/>
  </material>
  <material name="blue">
    <color rgba="0.0 0.0 1.0 1.0"/>
  </material>
  <!-- 
    These properties must be observed by any machine
    that wants to be defined as a turtlebot. Refer
    to the REP for more details.
    
    http://www.ros.org/reps/rep-0119.html
   -->
  <link name="base_footprint"/>
  <!--
       Base link is set at the bottom of the base mould.
       This is done to be compatible with the way base link
       was configured for turtlebot 1. Refer to
       https://github.com/turtlebot/turtlebot/issues/40
       To put the base link at the more oft used wheel
       axis, set the z-distance from the base_footprint
       to 0.352.
      -->
  <joint name="base_joint" type="fixed">
    <origin rpy="0 0 0" xyz="0 0 0.0102"/>
    <parent link="base_footprint"/>
    <child link="base_link"/>
  </joint>
  <link name="base_link">
    <visual>
      <geometry>
        <!-- new mesh -->
        <mesh filename="package://kobuki_description/meshes/main_body.dae"/>
      </geometry>
      <origin rpy="0 0 0" xyz="0.001 0 0.05199"/>
    </visual>
    <collision name="base">
      <geometry>
        <cylinder length="0.10938" radius="0.178"/>
      </geometry>
      <origin rpy="0 0 0" xyz="0.0 0 0.05949"/>
    </collision>
    <inertial>
      <!-- COM experimentally determined -->
      <origin xyz="0.01 0 0"/>
      <mass value="2.4"/>
      <!-- 2.4/2.6 kg for small/big battery pack -->
      <!-- Kobuki's inertia tensor is approximated by a cylinder with homogeneous mass distribution
             More details: http://en.wikipedia.org/wiki/List_of_moment_of_inertia_tensors
             m = 2.4 kg; h = 0.09 m; r = 0.175 m
             ixx = 1/12 * m * (3 * r^2 + h^2)
             iyy = 1/12 * m * (3 * r^2 + h^2)
             izz = 1/2 * m * r^2
          -->
      <inertia ixx="0.019995" ixy="0.0" ixz="0.0" iyy="0.019995" iyz="0.0" izz="0.03675"/>
    </inertial>
  </link>
  <joint name="wheel_left_joint" type="continuous">
    <parent link="base_link"/>
    <child link="wheel_left_link"/>
    <origin rpy="-1.5707963267948966 0 0" xyz="0.00 0.115 0.0250"/>
    <axis xyz="0 0 1"/>
  </joint>
  <link name="wheel_left_link">
    <visual>
      <geometry>
        <mesh filename="package://kobuki_description/meshes/wheel.dae"/>
      </geometry>
      <origin rpy="0 0 0" xyz="0 0 0"/>
    </visual>
    <collision>
      <geometry>
        <cylinder length="0.0206" radius="0.0352"/>
      </geometry>
      <origin rpy="0 0 0" xyz="0 0 0"/>
    </collision>
    <inertial>
      <mass value="0.01"/>
      <origin xyz="0 0 0"/>
      <inertia ixx="0.001" ixy="0.0" ixz="0.0" iyy="0.001" iyz="0.0" izz="0.001"/>
    </inertial>
  </link>
  <joint name="wheel_right_joint" type="continuous">
    <parent link="base_link"/>
    <child link="wheel_right_link"/>
    <origin rpy="-1.5707963267948966 0 0" xyz="0.00 -0.115 0.0250"/>
    <axis xyz="0 0 1"/>
  </joint>
  <link name="wheel_right_link">
    <visual>
      <geometry>
        <mesh filename="package://kobuki_description/meshes/wheel.dae"/>
      </geometry>
      <origin rpy="0 0 0" xyz="0 0 0"/>
    </visual>
    <collision>
      <geometry>
        <cylinder length="0.0206" radius="0.0350"/>
      </geometry>
      <origin rpy="0 0 0" xyz="0 0 0"/>
    </collision>
    <inertial>
      <mass value="0.01"/>
      <origin xyz="0 0 0"/>
      <inertia ixx="0.001" ixy="0.0" ixz="0.0" iyy="0.001" iyz="0.0" izz="0.001"/>
    </inertial>
  </link>
  <joint name="caster_front_joint" type="fixed">
    <parent link="base_link"/>
    <child link="caster_front_link"/>
    <origin rpy="-1.5707963267948966 0 0" xyz="0.115 0.0 0.007"/>
  </joint>
  <link name="caster_front_link">
    <collision>
      <geometry>
        <cylinder length="0.0176" radius="0.017"/>
      </geometry>
      <origin rpy="0 0 0" xyz="0 0 0"/>
    </collision>
    <inertial>
      <mass value="0.01"/>
      <origin xyz="0 0 0"/>
      <inertia ixx="0.001" ixy="0.0" ixz="0.0" iyy="0.001" iyz="0.0" izz="0.001"/>
    </inertial>
  </link>
  <joint name="caster_back_joint" type="fixed">
    <parent link="base_link"/>
    <child link="caster_back_link"/>
    <origin rpy="-1.5707963267948966 0 0" xyz="-0.135 0.0 0.009"/>
  </joint>
  <link name="caster_back_link">
    <collision>
      <geometry>
        <cylinder length="0.0176" radius="0.017"/>
      </geometry>
      <origin rpy="0 0 0" xyz="0 0 0"/>
    </collision>
    <inertial>
      <mass value="0.01"/>
      <origin xyz="0 0 0"/>
      <inertia ixx="0.001" ixy="0.0" ixz="0.0" iyy="0.001" iyz="0.0" izz="0.001"/>
    </inertial>
  </link>
  <!-- Kobuki's sensors -->
  <joint name="gyro_joint" type="fixed">
    <axis xyz="0 1 0"/>
    <origin rpy="0 0 0" xyz="0.056 0.062 0.0202"/>
    <parent link="base_link"/>
    <child link="gyro_link"/>
  </joint>
  <link name="gyro_link">
    <inertial>
      <mass value="0.001"/>
      <origin rpy="0 0 0" xyz="0 0 0"/>
      <inertia ixx="0.0001" ixy="0" ixz="0" iyy="0.000001" iyz="0" izz="0.0001"/>
    </inertial>
  </link>
  <joint name="cliff_sensor_left_joint" type="fixed">
    <origin rpy="0 1.5707963267948966 0" xyz="0.08734 0.13601 0.0214"/>
    <parent link="base_link"/>
    <child link="cliff_sensor_left_link"/>
  </joint>
  <link name="cliff_sensor_left_link">
    <inertial>
      <mass value="0.0001"/>
      <origin xyz="0 0 0"/>
      <inertia ixx="0.0001" ixy="0.0" ixz="0.0" iyy="0.0001" iyz="0.0" izz="0.0001"/>
    </inertial>
  </link>
  <joint name="cliff_sensor_right_joint" type="fixed">
    <origin rpy="0 1.5707963267948966 0" xyz="0.085 -0.13601 0.0214"/>
    <parent link="base_link"/>
    <child link="cliff_sensor_right_link"/>
  </joint>
  <link name="cliff_sensor_right_link">
    <inertial>
      <mass value="0.0001"/>
      <origin xyz="0 0 0"/>
      <inertia ixx="0.0001" ixy="0.0" ixz="0.0" iyy="0.0001" iyz="0.0" izz="0.0001"/>
    </inertial>
  </link>
  <joint name="cliff_sensor_front_joint" type="fixed">
    <origin rpy="0 1.5707963267948966 0" xyz="0.156 0.00 0.0214"/>
    <parent link="base_link"/>
    <child link="cliff_sensor_front_link"/>
  </joint>
  <link name="cliff_sensor_front_link">
    <inertial>
      <mass value="0.0001"/>
      <origin xyz="0 0 0"/>
      <inertia ixx="0.0001" ixy="0.0" ixz="0.0" iyy="0.0001" iyz="0.0" izz="0.0001"/>
    </inertial>
  </link>
  <stack_hexagons parent="base_link"/>
  <joint name="arm_base_fixed_joint" type="fixed">
    <parent link="plate_top_link"/>
    <child link="arm_base_link"/>
    <origin rpy="0 0 0" xyz="0.0 0.0 0.0"/>
    <axis xyz="0 0 1"/>
    <limit effort="30" lower="-3.141592653589793" upper="3.141592653589793" velocity="1.5707963267948966"/>
  </joint>
  <link name="arm_base_link">
    <visual>
      <origin rpy="0 0 0" xyz="0.0845 0 0"/>
      <geometry>
        <mesh filename="package://sobit_education_description/meshes/Manipulator_X4_Joint1_fix.dae"/>
      </geometry>
    </visual>
    <inertial>
      <origin rpy="0 0 0" xyz="0.0845 0 0"/>
      <mass value="0.08"/>
      <inertia ixx="1.0" ixy="0.0" ixz="0.0" iyy="1.0" iyz="0.0" izz="1.0"/>
    </inertial>
  </link>
  <joint name="arm_roll_joint" type="revolute">
    <parent link="arm_base_link"/>
    <child link="arm_roll_link"/>
    <origin rpy="0 0 0" xyz="0.13577 0.0 0.04314"/>
    <axis xyz="0 0 -1"/>
    <limit effort="30" lower="-3.141592653589793" upper="3.141592653589793" velocity="1.5707963267948966"/>
  </joint>
  <link name="arm_roll_link">
    <visual>
      <origin rpy="0 0 0" xyz="-0.001 0 -0.0005"/>
      <geometry>
        <mesh filename="package://sobit_education_description/meshes/Manipulator_X4_Joint2_fix.dae"/>
      </geometry>
    </visual>
    <inertial>
      <origin rpy="0 0 0" xyz="0 0 0.0"/>
      <mass value="0.08"/>
      <inertia ixx="1.0" ixy="0.0" ixz="0.0" iyy="1.0" iyz="0.0" izz="1.0"/>
    </inertial>
  </link>
  <joint name="arm_flex_joint_rgt" type="revolute">
    <parent link="arm_roll_link"/>
    <child link="arm_flex_link"/>
    <origin rpy="0 0 0" xyz="0.0 0.0 0.0407"/>
    <axis xyz="0 -1 0"/>
    <limit effort="30" lower="-1.5707963267948966" upper="1.5707963267948966" velocity="1.5707963267948966"/>
  </joint>
  <link name="arm_flex_link">
    <visual>
      <origin rpy="0 0 0" xyz="0 0.00025 0"/>
      <geometry>
        <mesh filename="package://sobit_education_description/meshes/Manipulator_X4_Joint3_fix.dae"/>
      </geometry>
    </visual>
    <inertial>
      <origin rpy="0 0 0" xyz="0 0 0"/>
      <mass value="0.08"/>
      <inertia ixx="1.0" ixy="0.0" ixz="0.0" iyy="1.0" iyz="0.0" izz="1.0"/>
    </inertial>
  </link>
  <joint name="arm_flex_joint_lft" type="revolute">
    <parent link="arm_roll_link"/>
    <child link="arm_flex_link_rgt_lft"/>
    <origin rpy="0 0 3.141592653589793" xyz="0.0 0.0 0.0"/>
    <axis xyz="0 -1 0"/>
    <limit effort="30" lower="-1.5707963267948966" upper="1.5707963267948966" velocity="1.5707963267948966"/>
  </joint>
  <link name="arm_flex_link_rgt_lft">
    <origin rpy="0 0 0" xyz="0 0 0"/>
  </link>
  <joint name="elbow_flex_joint_rgt" type="revolute">
    <parent link="arm_flex_link"/>
    <child link="elbow_flex_link"/>
    <origin rpy="0 0 0" xyz="0.0235 0.0 0.148"/>
    <axis xyz="0 -1 0"/>
    <limit effort="30" lower="-1.5707963267948966" upper="1.4155" velocity="1.5707963267948966"/>
  </joint>
  <link name="elbow_flex_link"/>
  <joint name="elbow_flex_joint_lft" type="revolute">
    <parent link="arm_flex_link"/>
    <child link="elbow_flex_link_rgt_lft"/>
    <origin rpy="0 0 3.141592653589793" xyz="0.0 0.0 0.0"/>
    <axis xyz="0 -1 0"/>
    <limit effort="30" lower="-1.5707963267948966" upper="1.4155" velocity="1.5707963267948966"/>
  </joint>
  <link name="elbow_flex_link_rgt_lft">
    <origin rpy="0 0 0" xyz="0 0 0"/>
  </link>
  <joint name="wrist_flex_dummy_joint" type="fixed">
    <parent link="elbow_flex_link"/>
    <child link="wrist_flex_dummy_link"/>
    <origin rpy="0 0 0" xyz="0 0 0.0"/>
    <axis xyz="0 0 1"/>
    <limit effort="30" lower="-0.1" upper="0.1" velocity="1.5707963267948966"/>
  </joint>
  <link name="wrist_flex_dummy_link">
    <visual>
      <origin rpy="0 1.5507963267948965 0" xyz="-0.0005 -0.0001 0"/>
      <geometry>
        <mesh filename="package://sobit_education_description/meshes/Manipulator_X4_Joint4_fix.dae"/>
      </geometry>
    </visual>
    <inertial>
      <origin rpy="0 0 0" xyz="0 0 0"/>
      <mass value="0.08"/>
      <inertia ixx="1.0" ixy="0.0" ixz="0.0" iyy="1.0" iyz="0.0" izz="1.0"/>
    </inertial>
  </link>
  <joint name="wrist_flex_joint" type="revolute">
    <parent link="wrist_flex_dummy_link"/>
    <child link="wrist_flex_link"/>
    <origin rpy="0 0 0" xyz="0.152 0.0 0.0"/>
    <axis xyz="0 -1 0"/>
    <limit effort="30" lower="-1.5707963267948966" upper="1.5707963267948966" velocity="1.5707963267948966"/>
  </joint>
  <link name="wrist_flex_link">
    <visual>
      <origin rpy="0 1.5707963267948966 0" xyz="-0.0005 -0.0001 0"/>
      <geometry>
        <mesh filename="package://sobit_education_description/meshes/Manipulator_X4_Gripper_fix.dae"/>
      </geometry>
    </visual>
    <inertial>
      <origin rpy="0 0 0" xyz="0 0 0"/>
      <mass value="0.08"/>
      <inertia ixx="1.0" ixy="0.0" ixz="0.0" iyy="1.0" iyz="0.0" izz="1.0"/>
    </inertial>
  </link>
  <position_joint_transmission joint="arm_roll_joint" reduction="1"/>
  <position_joint_transmission joint="arm_flex_joint_rgt" reduction="1"/>
  <position_joint_transmission joint="arm_flex_joint_lft" reduction="1"/>
  <position_joint_transmission joint="elbow_flex_joint_rgt" reduction="1"/>
  <position_joint_transmission joint="elbow_flex_joint_lft" reduction="1"/>
  <position_joint_transmission joint="wrist_flex_joint" reduction="1"/>
  <joint name="hand_motor_dummy_joint" type="fixed">
    <parent link="wrist_flex_link"/>
    <child link="hand_motor_dummy_link"/>
    <origin rpy="0 0 0" xyz="0.0 0.0 0.0"/>
    <axis xyz="0 1 0"/>
    <limit effort="30" lower="-1.5707963267948966" upper="1.5707963267948966" velocity="1.5707963267948966"/>
  </joint>
  <link name="hand_motor_dummy_link"/>
  <joint name="hand_motor_joint" type="revolute">
    <parent link="hand_motor_dummy_link"/>
    <child link="hand_motor_link"/>
    <axis xyz="1 0 0"/>
    <limit effort="1" lower="0.0" upper="1.5707963267948966" velocity="1"/>
  </joint>
  <link name="hand_motor_link"/>
  <joint name="hand_motor_l_joint" type="revolute">
    <parent link="hand_motor_dummy_link"/>
    <child link="hand_motor_l_link"/>
    <origin rpy="0 0 0" xyz="0.0455 0.0165 0.0"/>
    <axis xyz="0 0 1"/>
    <limit effort="1" lower="-1.5707963267948966" upper="0.0" velocity="1"/>
    <mimic joint="hand_motor_joint" multiplier="1.0" offset="-0.1"/>
  </joint>
  <link name="hand_motor_l_link">
    <visual>
      <origin rpy="0 0 0" xyz="0.04 -0.017 0.0015"/>
      <geometry>
        <mesh filename="package://sobit_education_description/meshes/sobit_edu_hand.dae"/>
      </geometry>
    </visual>
    <inertial>
      <origin rpy="0 0 0" xyz="0 0 0"/>
      <mass value="0.08"/>
      <inertia ixx="1.0" ixy="0.0" ixz="0.0" iyy="1.0" iyz="0.0" izz="1.0"/>
    </inertial>
  </link>
  <joint name="hand_motor_r_joint" type="revolute">
    <parent link="hand_motor_dummy_link"/>
    <child link="hand_motor_r_link"/>
    <origin rpy="0 0 0" xyz="0.0455 -0.0165 0.0"/>
    <axis xyz="0 0 1"/>
    <limit effort="1" lower="0" upper="1.5707963267948966" velocity="1"/>
    <mimic joint="hand_motor_joint" multiplier="-1.0" offset="0.1"/>
  </joint>
  <link name="hand_motor_r_link">
    <visual>
      <origin rpy="3.141592653589793 0 0" xyz="0.04 0.017 -0.005"/>
      <geometry>
        <mesh filename="package://sobit_education_description/meshes/sobit_edu_hand.dae"/>
      </geometry>
    </visual>
    <inertial>
      <origin rpy="0 0 3.141592653589793" xyz="0 0 0"/>
      <mass value="0.08"/>
      <inertia ixx="1.0" ixy="0.0" ixz="0.0" iyy="1.0" iyz="0.0" izz="1.0"/>
    </inertial>
  </link>
  <joint name="hand_motor_center_joint" type="fixed">
    <parent link="wrist_flex_link"/>
    <child link="hand_motor_center_link"/>
    <origin rpy="0 0 0" xyz="0.15 0.0 0.0"/>
    <axis xyz="0 1 0"/>
    <limit effort="30" lower="-1.5707963267948966" upper="1.5707963267948966" velocity="1.5707963267948966"/>
  </joint>
  <link name="hand_motor_center_link"/>
  <position_joint_transmission joint="hand_motor_joint" reduction="1"/>
  <joint name="base_pole_joint" type="fixed">
    <parent link="plate_top_link"/>
    <child link="base_pole_link"/>
    <origin rpy="1.5707963267948966 0 1.5707963267948966" xyz="-0.06 0.0 0.0"/>
    <axis xyz="0 0 1"/>
    <limit effort="30" lower="-3.141592653589793" upper="3.141592653589793" velocity="1.5707963267948966"/>
  </joint>
  <link name="base_pole_link">
    <visual>
      <origin rpy="0 0 0" xyz="-0.01 0 -0.01"/>
      <geometry>
        <mesh filename="package://sobit_education_description/meshes/sobit_edu_pole.dae"/>
      </geometry>
    </visual>
    <inertial>
      <origin rpy="0 0 0" xyz="0.0 0 0.0"/>
      <mass value="1"/>
      <inertia ixx="1.0" ixy="0.0" ixz="0.0" iyy="1.0" iyz="0.0" izz="1.0"/>
    </inertial>
  </link>
  <joint name="base_urg_sup_joint" type="fixed">
    <origin rpy="0 0 0" xyz="0.194084 0.0 0.0085"/>
    <parent link="plate_bottom_link"/>
    <child link="base_urg_sup_link"/>
    <axis xyz="0 0 1"/>
    <limit effort="30" lower="-3.14" upper="3.14" velocity="1.571"/>
  </joint>
  <link name="base_urg_sup_link">
    <visual>
      <origin rpy="0.0 0.0 4.71238898038469" xyz="0.0 0 0.0"/>
      <geometry>
        <mesh filename="package://sobit_education_description/meshes/sobit_edu_urg_sup.dae"/>
      </geometry>
    </visual>
    <inertial>
      <!-- <origin rpy="0 0 ${M_PI*2.0}" xyz="0.0 0 0.0"/> -->
      <origin rpy="0.0 0.0 0.0" xyz="0.0 0 0.0"/>
      <mass value="0.000001"/>
      <inertia ixx="0.0001" ixy="0.0" ixz="0.0" iyy="0.0001" iyz="0.0" izz="0.0001"/>
    </inertial>
  </link>
  <joint name="xtion_pan_joint" type="revolute">
    <parent link="base_pole_link"/>
    <child link="xtion_pan_link"/>
    <origin rpy="-1.5707963267948966 -1.5707963267948966 0" xyz="0 0.396 0.191"/>
    <axis xyz="0 0 -1"/>
    <limit effort="30" lower="-1.5707963267948966" upper="1.5707963267948966" velocity="1.5707963267948966"/>
  </joint>
  <link name="xtion_pan_link">
    <visual>
      <origin rpy="0 0 1.5707963267948966" xyz="0.0138 -0.02159 -0.0005"/>
      <geometry>
        <mesh filename="package://sobit_education_description/meshes/sobit_edu_pan.dae"/>
      </geometry>
    </visual>
    <inertial>
      <origin rpy="0 0 0" xyz="0 0 0"/>
      <mass value="0.08"/>
      <inertia ixx="1.0" ixy="0.0" ixz="0.0" iyy="1.0" iyz="0.0" izz="1.0"/>
    </inertial>
  </link>
  <joint name="xtion_tilt_joint" type="revolute">
    <parent link="xtion_pan_link"/>
    <child link="xtion_tilt_link"/>
    <origin rpy="-1.5707963267948966 -1.5707963267948966 0" xyz="0.0 0.0 0.0428"/>
    <axis xyz="0 0 -1"/>
    <limit effort="30" lower="-1.5707963267948966" upper="1.5707963267948966" velocity="1.5707963267948966"/>
  </joint>
  <link name="xtion_tilt_link">
    <visual>
      <origin rpy="0 1.5707963267948966 -1.5707963267948966" xyz="0.00 0.0 0.0"/>
      <geometry>
        <mesh filename="package://sobit_education_description/meshes/sobit_edu_tilt.dae"/>
      </geometry>
    </visual>
    <inertial>
      <origin rpy="0 0 0" xyz="0 0 0"/>
      <mass value="0.08"/>
      <inertia ixx="1.0" ixy="0.0" ixz="0.0" iyy="1.0" iyz="0.0" izz="1.0"/>
    </inertial>
  </link>
  <joint name="xtion_double_sided_tape_joint" type="fixed">
    <parent link="xtion_tilt_link"/>
    <child link="xtion_double_sided_tape_link"/>
    <origin rpy="0.05 0 -0.06" xyz="0.02050 0.0 0.0"/>
    <axis xyz="0 0 -1"/>
    <limit effort="30" lower="-1.5707963267948966" upper="1.5707963267948966" velocity="1.5707963267948966"/>
  </joint>
  <link name="xtion_double_sided_tape_link"/>
  <position_joint_transmission joint="xtion_pan_joint" reduction="1"/>
  <position_joint_transmission joint="xtion_tilt_joint" reduction="1"/>
  <joint name="camera_rgb_joint" type="fixed">
    <origin rpy="1.5707963267948966 0.0 1.5707963267948966" xyz="0.01088 0.02 0.0220"/>
    <parent link="xtion_double_sided_tape_link"/>
    <child link="rgb_link"/>
  </joint>
  <link name="rgb_link"/>
  <joint name="camera_rgb_optical_joint" type="fixed">
    <origin rpy="-1.5707963267948966 0 -1.5707963267948966" xyz="0 0 0"/>
    <parent link="rgb_link"/>
    <child link="camera_rgb_optical_frame"/>
  </joint>
  <link name="camera_rgb_optical_frame"/>
  <joint name="camera_joint" type="fixed">
    <origin rpy="0 0 0" xyz="0 -0.022 0"/>
    <parent link="rgb_link"/>
    <child link="camera_link"/>
  </joint>
  <link name="camera_link">
    <visual>
      <origin rpy="0 0 0" xyz="-0.015 0.0035 0.004"/>
      <geometry>
        <mesh filename="package://turtlebot_description/meshes/sensors/xtion_pro_camera.dae"/>
      </geometry>
    </visual>
    <collision>
      <origin rpy="0 0 0" xyz="0.0 0.0 0.0"/>
      <geometry>
        <box size="0.0730 0.2760 0.0720"/>
      </geometry>
    </collision>
    <inertial>
      <mass value="0.170"/>
      <origin xyz="0 0 0"/>
      <inertia ixx="0.001152600" ixy="0.0" ixz="0.0" iyy="0.000148934" iyz="0.0" izz="0.001154654"/>
    </inertial>
  </link>
  <joint name="camera_depth_joint" type="fixed">
    <origin rpy="0 0 0" xyz="0 0.027 0"/>
    <parent link="rgb_link"/>
    <child link="depth_link"/>
  </joint>
  <link name="depth_link"/>
  <joint name="camera_depth_optical_joint" type="fixed">
    <origin rpy="-1.5707963267948966 0 -1.5707963267948966" xyz="0 0 0"/>
    <parent link="depth_link"/>
    <child link="camera_depth_optical_frame"/>
  </joint>
  <link name="camera_depth_optical_frame"/>
  <joint name="mic_stand_joint" type="fixed">
    <parent link="base_pole_link"/>
    <child link="mic_stand_link"/>
    <origin rpy="-1.5707963267948966 0 0" xyz="0.0 0.62 0.17"/>
    <axis xyz="0 1 0"/>
  </joint>
  <link name="mic_stand_link">
    <collision>
      <origin rpy="0 0 0" xyz="0 0 0.025"/>
      <geometry>
        <cylinder length="0.05" radius="0.015"/>
      </geometry>
    </collision>
    <visual>
      <origin rpy="0 0 0" xyz="0 0 0.025"/>
      <geometry>
        <cylinder length="0.05" radius="0.015"/>
      </geometry>
      <material name="black"/>
    </visual>
    <inertial>
      <origin rpy="0 0 0" xyz="0 0 0.025"/>
      <mass value="1"/>
      <inertia ixx="1.0" ixy="0.0" ixz="0.0" iyy="1.0" iyz="0.0" izz="1.0"/>
    </inertial>
  </link>
  <joint name="mic_joint" type="fixed">
    <parent link="mic_stand_link"/>
    <child link="mic"/>
    <origin rpy="0.78 0 0" xyz="0.0 0.0 0.05"/>
    <axis xyz="0 1 0"/>
  </joint>
  <link name="mic">
    <collision>
      <origin rpy="0 0 0" xyz="0 0 0.05"/>
      <geometry>
        <cylinder length="0.18" radius="0.01"/>
      </geometry>
    </collision>
    <visual>
      <origin rpy="0 0 0" xyz="0 0 0.05"/>
      <geometry>
        <cylinder length="0.18" radius="0.01"/>
      </geometry>
      <material name="black"/>
    </visual>
    <inertial>
      <origin rpy="0 0 0" xyz="0 0 0.05"/>
      <mass value="1"/>
      <inertia ixx="1.0" ixy="0.0" ixz="0.0" iyy="1.0" iyz="0.0" izz="1.0"/>
    </inertial>
  </link>
  <joint name="matrix_base_joint" type="fixed">
    <parent link="base_pole_link"/>
    <child link="matrix_base_link"/>
    <origin rpy="-1.5707963267948966 -1.5707963267948966 0" xyz="0.0 0.62 0.07"/>
    <axis xyz="0 1 0"/>
  </joint>
  <link name="matrix_base_link">
    <collision>
      <origin rpy="0 0 0" xyz="0 0 0"/>
      <geometry>
        <box size="0.096 0.062 0.028"/>
      </geometry>
    </collision>
    <visual>
      <origin rpy="0 0 0" xyz="0 0 0"/>
      <geometry>
        <box size="0.096 0.062 0.028"/>
      </geometry>
      <material name="white"/>
    </visual>
    <inertial>
      <origin rpy="0 0 0" xyz="0 0 0"/>
      <mass value="1"/>
      <inertia ixx="1.0" ixy="0.0" ixz="0.0" iyy="1.0" iyz="0.0" izz="1.0"/>
    </inertial>
  </link>
  <joint name="matrix_board_joint" type="fixed">
    <parent link="matrix_base_link"/>
    <child link="matrix_board_link"/>
    <origin rpy="0 0 0" xyz="0 0 0.015"/>
    <axis xyz="0 1 0"/>
  </joint>
  <!-- MATRIX_Creator -->
  <link name="matrix_board_link">
    <collision>
      <origin rpy="0 0 0" xyz="0 0 0"/>
      <geometry>
        <cylinder length="0.002" radius="0.054"/>
      </geometry>
    </collision>
    <visual>
      <origin rpy="0 0 0" xyz="0 0 0"/>
      <geometry>
        <cylinder length="0.002" radius="0.054"/>
      </geometry>
      <material name="blue"/>
    </visual>
    <inertial>
      <origin rpy="0 0 0" xyz="0 0 0"/>
      <mass value="1"/>
      <inertia ixx="1.0" ixy="0.0" ixz="0.0" iyy="1.0" iyz="0.0" izz="1.0"/>
    </inertial>
  </link>
  <joint name="matrix_joint" type="fixed">
    <parent link="matrix_board_link"/>
    <child link="matrix"/>
    <origin rpy="0 0 0" xyz="0 0 0.0001"/>
    <axis xyz="0 1 0"/>
  </joint>
  <!-- Sensor -->
  <link name="matrix">
    <collision>
      <origin rpy="0 0 0" xyz="0 0 0"/>
      <geometry>
        <box size="0.012 0.012 0.002"/>
      </geometry>
    </collision>
    <visual>
      <origin rpy="0 0 0" xyz="0 0 0"/>
      <geometry>
        <box size="0.012 0.012 0.002"/>
      </geometry>
      <material name="white"/>
    </visual>
    <inertial>
      <origin rpy="0 0 0" xyz="0 0 0"/>
      <mass value="1"/>
      <inertia ixx="1.0" ixy="0.0" ixz="0.0" iyy="1.0" iyz="0.0" izz="1.0"/>
    </inertial>
  </link>
  <joint name="base_laser_joint" type="fixed">
    <!-- <origin xyz="0.18 0.0 0.38" rpy="0 0 0" /> -->
    <origin rpy="0 0 0" xyz="0.0 0.0 0.0"/>
    <parent link="base_urg_sup_link"/>
    <child link="base_laser_link"/>
    <origin rpy="0 0 0" xyz="0.13525 0.0 0.034"/>
    <axis xyz="0 0 1"/>
    <limit effort="30" lower="-3.14" upper="3.14" velocity="1.571"/>
  </joint>
  <link name="base_laser_link">
    <visual>
      <geometry>
        <mesh filename="package://sobit_education_description/meshes/UST-20LX.dae"/>
      </geometry>
    </visual>
    <inertial>
      <mass value="0.000001"/>
      <origin xyz="0 0 0"/>
      <inertia ixx="0.0001" ixy="0.0" ixz="0.0" iyy="0.0001" iyz="0.0" izz="0.0001"/>
    </inertial>
  </link>
</robot>

