<?xml version="1.0"?>
<!-- The common turtlebot library of xacros for easy reference -->
<robot xmlns:xacro="http://ros.org/wiki/xacro">
  <!-- General -->
  <xacro:include filename="$(find turtlebot_description)/urdf/common_properties.urdf.xacro"/>
  <xacro:include filename="$(find turtlebot_description)/urdf/turtlebot_properties.urdf.xacro"/>

  <!-- urg -->
  <joint name="laser" type="fixed">
    <origin xyz="0.205 0.0 0.01" rpy="0 0 0" />
    <parent link="base_link" />
    <child link="base_laser_link" />
    <origin rpy="0 0 0" xyz="0.13525 0.0 0.034"/>
    <axis xyz="0 0 1"/>
    <limit effort="30" lower="-3.14" upper="3.14" velocity="1.571"/>
  </joint>

  <link name="base_laser_link">
    <visual>
      <geometry>
        <mesh filename="package://sobit_education_description/model/dae/UST-20LX.dae"/>
      </geometry>
      <material name="Black" />
    </visual>
    <inertial>
      <mass value="0.000001" />
      <origin xyz="0 0 0" />
      <inertia ixx="0.0001" ixy="0.0" ixz="0.0"
        iyy="0.0001" iyz="0.0"
        izz="0.0001" />
    </inertial>
  </link>

  <material name="red">
    <color rgba="1.0 0.0 0.0 1.0"/>
  </material>
  <material name="green">
    <color rgba="0.0 1.0 0.0 1.0"/>
  </material>
  <material name="blue">
    <color rgba="0.0 0.0 1.0 1.0"/>
  </material>
  <material name="black">
    <color rgba="0.0 0.0 0.0 1.0"/>
  </material>
  <material name="white">
    <color rgba="0.87 0.90 0.87 1.0"/>
  </material>
  <material name="orange">
    <color rgba="1.0 0.4 0.0 1.0"/>
  </material>

  <joint name="fixed" type="fixed">
    <parent link="plate_top_link"/>
    <child link="base_arm_link"/>
    <origin rpy="0 0 0" xyz="0.0 0.0 0.0"/>
    <axis xyz="0 0 1"/>
    <limit effort="30" lower="-3.14" upper="3.14" velocity="1.571"/>
  </joint>

  <!-- arm_link -->
  <link name="base_arm_link">
    <collision>
      <geometry>
        <mesh filename="package://sobit_education_description/model/dae/Manipulator_X4_Joint1_fix.dae"/>
      </geometry>
    </collision>
    <visual>
      <origin rpy="0 0 0" xyz="0.0845 0 0"/>
      <geometry>
        <mesh filename="package://sobit_education_description/model/dae/Manipulator_X4_Joint1_fix.dae"/>
      </geometry>
      <material name="black"/>
    </visual>
    <inertial>
      <origin rpy="0 0 0" xyz="0.0845 0 0"/>
      <mass value="0.08"/>
      <inertia ixx="1.0" ixy="0.0" ixz="0.0" iyy="1.0" iyz="0.0" izz="1.0"/>
    </inertial>
  </link>

  <joint name="arm_roll_joint" type="revolute">
    <parent link="base_arm_link"/>
    <child link="arm_roll_link"/>
    <origin rpy="0 0 0" xyz="0.13525 0.0 0.034"/>
    <axis xyz="0 0 1"/>
    <limit effort="30" lower="-3.14" upper="3.14" velocity="1.571"/>
  </joint>

  <link name="arm_roll_link">
    <collision>
      <geometry>
        <mesh filename="package://sobit_education_description/model/dae/Manipulator_X4_Joint2_fix.dae"/>
      </geometry>
    </collision>
    <visual>
      <origin rpy="0 0 0" xyz="0 0 0.0"/>
      <geometry>
        <mesh filename="package://sobit_education_description/model/dae/Manipulator_X4_Joint2_fix.dae"/>
      </geometry>
      <material name="black"/>
    </visual>
    <inertial>
      <origin rpy="0 0 0" xyz="0 0 0.0"/>
      <mass value="0.08"/>
      <inertia ixx="1.0" ixy="0.0" ixz="0.0" iyy="1.0" iyz="0.0" izz="1.0"/>
    </inertial>
  </link>
  <joint name="arm_flex_joint" type="revolute">
    <parent link="arm_roll_link"/>
    <child link="arm_flex_dummy_link"/>
    <origin rpy="0 0 0" xyz="0.0 0.0 0.0421"/>
    <axis xyz="0 1 0"/>
    <limit effort="30" lower="0" upper="1.57" velocity="1.571"/>
  </joint>

  <link name="arm_flex_dummy_link"/>
  <joint name="arm_flex_dummy_joint" type="fixed">
    <parent link="arm_flex_dummy_link"/>
    <child link="arm_flex_link"/>
    <origin rpy="0 0 0" xyz="0 0 0.0"/>
    <axis xyz="0 0 1"/>
    <limit effort="30" lower="-0.1" upper="0.1" velocity="1.571"/>
  </joint>

  <link name="arm_flex_link">
    <collision>
      <geometry>
        <mesh filename="package://sobit_education_description/model/dae/Manipulator_X4_Joint3_fix.dae"/>
      </geometry>
    </collision>
    <visual>
      <origin rpy="0 0 0" xyz="0 0 0"/>
      <geometry>
        <mesh filename="package://sobit_education_description/model/dae/Manipulator_X4_Joint3_fix.dae"/>
      </geometry>
      <material name="black"/>
    </visual>
    <inertial>
      <origin rpy="0 0 0" xyz="0 0 0"/>
      <mass value="0.08"/>
      <inertia ixx="1.0" ixy="0.0" ixz="0.0" iyy="1.0" iyz="0.0" izz="1.0"/>
    </inertial>
  </link>

  <joint name="elbow_flex_joint" type="revolute">
    <parent link="arm_flex_link"/>
    <child link="elbow_flex_dummy_link"/>
    <origin rpy="0 1.57 0" xyz="0.024 0.0 0.148"/>
    <axis xyz="0 1 0"/>
    <limit effort="30" lower="-1.57" upper="1.4155" velocity="1.571"/>
  </joint>

  <link name="elbow_flex_dummy_link"/>
  <joint name="elbow_flex_dummy_joint" type="fixed">
    <parent link="elbow_flex_dummy_link"/>
    <child link="wrist_flex_link"/>
    <origin rpy="0 0 0" xyz="0 0 0.0"/>
    <axis xyz="0 0 1"/>
    <limit effort="30" lower="-0.1" upper="0.1" velocity="1.571"/>
  </joint>

  <link name="wrist_flex_link">
    <collision>
      <geometry>
        <mesh filename="package://sobit_education_description/model/dae/Manipulator_X4_Joint4_fix.dae"/>
      </geometry>
    </collision>
    <visual>
      <origin rpy="0 0 0" xyz="0 0 0"/>
      <geometry>
        <mesh filename="package://sobit_education_description/model/dae/Manipulator_X4_Joint4_fix.dae"/>
      </geometry>
      <material name="black"/>
    </visual>
    <inertial>
      <origin rpy="0 0 0" xyz="0 0 0"/>
      <mass value="0.08"/>
      <inertia ixx="1.0" ixy="0.0" ixz="0.0" iyy="1.0" iyz="0.0" izz="1.0"/>
    </inertial>
  </link>

  <joint name="wrist_flex_joint" type="revolute">
    <parent link="wrist_flex_link"/>
    <child link="hand_motor_link"/>
    <origin rpy="0 0 0" xyz="0.0 0.0 0.15"/>
    <axis xyz="0 1 0"/>
    <limit effort="30" lower="-1.57" upper="1.57" velocity="1.571"/>
  </joint>

  <link name="hand_motor_link">
    <collision>
      <geometry>
        <mesh filename="package://sobit_education_description/model/dae/Manipulator_X4_Gripper_fix.dae"/>
      </geometry>
    </collision>
    <visual>
      <origin rpy="0 0 0" xyz="0 0 0"/>
      <geometry>
        <mesh filename="package://sobit_education_description/model/dae/Manipulator_X4_Gripper_fix.dae"/>
      </geometry>
      <material name="black"/>
    </visual>
    <inertial>
      <origin rpy="0 0 0" xyz="0 0 0"/>
      <mass value="0.08"/>
      <inertia ixx="1.0" ixy="0.0" ixz="0.0" iyy="1.0" iyz="0.0" izz="1.0"/>
    </inertial>
  </link>

	<joint name="hand_motor_joint" type="revolute">
		<parent link="hand_motor_link"/>
		<child link="hand_motor_dummy_link"/>
		<axis xyz="1 0 0" />
		<limit lower="0.0" upper="1.57" effort="1" velocity="1" />
	</joint>

  <link name="hand_motor_dummy_link"/>

  <joint name="hand_motor_l_joint" type="revolute">
		<parent link="hand_motor_link"/>
		<child link="hand_motor_l_link"/>
		<origin rpy="0.78 0 0" xyz="0.0 0.01 0.04225"/>
		<axis xyz="1 0 0" />
		<limit lower="-1.57" upper="0.0" effort="1" velocity="1" />
    <mimic joint="hand_motor_joint" multiplier="-1.0" offset="0.1"/>
	</joint>

	<joint name="hand_motor_r_joint" type="revolute">
		<parent link="hand_motor_link"/>
		<child link="hand_motor_r_link"/>
		<origin rpy="-0.78 0 0" xyz="0.0 -0.01 0.04225"/>
		<axis xyz="1 0 0" />
		<limit lower="0" upper="1.57" effort="1" velocity="1" />
    <mimic joint="hand_motor_joint" multiplier="1.0" offset="-0.1"/>
	</joint>

	<link name="hand_motor_l_link">
		<collision>
			<geometry>
				<mesh filename="package://sobit_education_description/model/dae/ManipulatorX4_Finger_right.dae"/>
			</geometry>
		</collision>
		<visual>
			<origin rpy="0 0 0" xyz="0 0 0"/>
			<geometry>
				<mesh filename="package://sobit_education_description/model/dae/ManipulatorX4_Finger_right.dae"/>
			</geometry>
			<material name="black">
				<color rgba="0.0 0.0 0.0 1.0"/>
			</material>
		</visual>
		<inertial>
			<origin rpy="0 0 0" xyz="0 0 0"/>
			<mass value="0.08"/>
			<inertia ixx="1.0" ixy="0.0" ixz="0.0" iyy="1.0" iyz="0.0" izz="1.0"/>
		</inertial>
	</link>

	<link name="hand_motor_r_link">
		<collision>
			<geometry>
				<mesh filename="package://sobit_education_description/model/dae/ManipulatorX4_Finger_right.dae"/>
			</geometry>
		</collision>
		<visual>
			<origin rpy="0 0 3.14" xyz="0 0 0"/>
			<geometry>
				<mesh filename="package://sobit_education_description/model/dae/ManipulatorX4_Finger_right.dae"/>
			</geometry>
			<material name="black">
				<color rgba="0.0 0.0 0.0 1.0"/>
			</material>
		</visual>
		<inertial>
			<origin rpy="0 0 3.14" xyz="0 0 0"/>
			<mass value="0.08"/>
			<inertia ixx="1.0" ixy="0.0" ixz="0.0" iyy="1.0" iyz="0.0" izz="1.0"/>
		</inertial>
	</link>

  <!-- xtion -->
  <joint name="base_xtion_pole_joint" type="fixed">
    <parent link="plate_top_link"/>
    <child link="base_xtion_pole_link"/>
    <origin rpy="0 0 0" xyz="0 0.0 0.0"/>
     <axis xyz="0 0 1"/>
     <limit effort="30" lower="-3.14" upper="3.14" velocity="1.571"/>
  </joint>

  <link name="base_xtion_pole_link">
    <collision>
      <origin rpy="0 0 0" xyz="-0.062 0 0.303"/>
      <geometry>
        <box size="0.02 0.02 0.6"/>
      </geometry>
    </collision>
    <visual>
      <origin rpy="0 0 0" xyz="-0.062 0 0.303"/>
      <geometry>
        <box size="0.02 0.02 0.6"/>
      </geometry>
      <material name="white"/>
    </visual>
    <inertial>
      <origin rpy="0 0 0" xyz="-0.062 0 0.303"/>
      <mass value="1"/>
      <inertia ixx="1.0" ixy="0.0" ixz="0.0" iyy="1.0" iyz="0.0" izz="1.0"/>
    </inertial>
  </link>
  <joint name="base_xtion_placed_joint" type="fixed">
    <parent link="base_xtion_pole_link"/>
    <child link="base_xtion_placed_link"/>
    <origin rpy="0 0 0" xyz="-0.062 0 0.373"/>
    <axis xyz="0 0 1"/>
    <limit effort="30" lower="-3.14" upper="3.14" velocity="1.571"/>
  </joint>

  <link name="base_xtion_placed_link">
    <collision>
      <origin rpy="0 0 0" xyz="0.08 0 0"/>
      <geometry>
        <box size="0.14 0.02 0.02"/>
      </geometry>
    </collision>
    <visual>
      <origin rpy="0 0 0" xyz="0.08 0 0"/>
      <geometry>
        <box size="0.14 0.02 0.02"/>
      </geometry>
      <material name="white"/>
    </visual>
    <inertial>
      <origin rpy="0 0 0" xyz="0.08 0 0.0"/>
      <mass value="1"/>
      <inertia ixx="1.0" ixy="0.0" ixz="0.0" iyy="1.0" iyz="0.0" izz="1.0"/>
    </inertial>
  </link>
  <joint name="xtion_stand_joint" type="fixed">
    <parent link="base_xtion_placed_link"/>
    <child link="xtion_stand_link"/>
    <origin rpy="0 0 0" xyz="0.14 0 0.0"/>
    <axis xyz="0 0 1"/>
    <limit effort="30" lower="-3.14" upper="3.14" velocity="1.571"/>
  </joint>

  <link name="xtion_stand_link">
    <collision>
      <origin rpy="0 0 0" xyz="0.0265 0 0.0155"/>
      <geometry>
        <box size="0.033 0.033 0.051"/>
      </geometry>
    </collision>
    <visual>
      <origin rpy="0 0 0" xyz="0.0265 0 0.0155"/>
      <geometry>
        <box size="0.033 0.033 0.051"/>
      </geometry>
      <material name="black"/>
    </visual>
    <inertial>
      <origin rpy="0 0 0" xyz="0.0265 0 0.0155"/>
      <mass value="1"/>
      <inertia ixx="1.0" ixy="0.0" ixz="0.0" iyy="1.0" iyz="0.0" izz="1.0"/>
    </inertial>
  </link>
  <joint name="xtion_tilt_joint" type="revolute">
    <parent link="xtion_stand_link"/>
    <child link="xtion_tilt_link"/>
    <origin rpy="0 0 0" xyz="0.0265 0 0.03"/>
    <axis xyz="0 1 0"/>
    <limit effort="30" lower="-1.57" upper="1.57" velocity="1.571"/>
  </joint>

  <link name="xtion_tilt_link">
    <collision>
      <origin rpy="0 0 0" xyz="0.0 0 0.014"/>
      <geometry>
        <box size="0.02 0.041 0.028"/>
      </geometry>
    </collision>
    <visual>
      <origin rpy="0 0 0" xyz="0.0 0 0.014"/>
      <geometry>
        <box size="0.02 0.041 0.028"/>
      </geometry>
      <material name="black"/>
    </visual>
    <inertial>
      <origin rpy="0 0 0" xyz="0.0 0 0.0"/>
      <mass value="1"/>
      <inertia ixx="1.0" ixy="0.0" ixz="0.0" iyy="1.0" iyz="0.0" izz="1.0"/>
    </inertial>
  </link>
  <joint name="xtion_fixed_joint" type="fixed">
    <parent link="xtion_tilt_link"/>
    <child link="xtion"/>
    <origin rpy="0 0 0" xyz="0.0 0 0.0"/>
    <axis xyz="0 1 0"/>
    <limit effort="30" lower="-0.17" upper="1.57" velocity="1.571"/>
  </joint>

  <link name="xtion">
    <visual>
      <origin xyz="-0.0 0.0 0.0405" rpy="0 0 0"/>
      <geometry>
        <mesh filename="package://turtlebot_description/meshes/sensors/xtion_pro_camera.dae"/>
      </geometry>
    </visual>
    <collision>
      <origin xyz="0.0 0.0 0.0405" rpy="0 0 0" />
      <geometry>
      <box size="0.0730 0.2760 0.0720"/>
    </geometry>
    </collision>
    <inertial>
      <mass value="0.170" />
      <origin xyz="0 0 0" />
      <inertia ixx="0.001152600" ixy="0.0" ixz="0.0"
                iyy="0.000148934" iyz="0.0"
                izz="0.001154654" />
    </inertial>
  </link>

  <!-- mic -->
  <joint name="base_mic_placed_joint" type="fixed">
    <parent link="base_xtion_pole_link"/>
    <child link="base_mic_placed_link"/>
    <origin rpy="0 0 0" xyz="-0.062 0 0.613"/>
    <axis xyz="0 1 0"/>
  </joint>
  <link name="base_mic_placed_link">
    <collision>
      <origin rpy="0 0 0" xyz="0.09 0 0.0"/>
      <geometry>
        <box size="0.2 0.02 0.02"/>
      </geometry>
    </collision>
    <visual>
      <origin rpy="0 0 0" xyz="0.09 0 0.0"/>
      <geometry>
        <box size="0.2 0.02 0.02"/>
      </geometry>
      <material name="white"/>
    </visual>
    <inertial>
      <origin rpy="0 0 0" xyz="0.0 0 0.613"/>
      <mass value="1"/>
      <inertia ixx="1.0" ixy="0.0" ixz="0.0" iyy="1.0" iyz="0.0" izz="1.0"/>
    </inertial>
  </link>
  <joint name="mic_stand_joint" type="fixed">
    <parent link="base_mic_placed_link"/>
    <child link="mic_stand_link"/>
    <origin rpy="0 0 0" xyz="0.175 0 0.01"/>
    <axis xyz="0 1 0"/>
  </joint>

  <link name="mic_stand_link">
    <collision>
      <origin rpy="0 0 0" xyz="0 0 0.025"/>
      <geometry>
        <cylinder radius="0.015" length="0.05"/>
      </geometry>
    </collision>
    <visual>
      <origin rpy="0 0 0" xyz="0 0 0.025"/>
      <geometry>
        <cylinder radius="0.015" length="0.05"/>
      </geometry>
      <material name="black"/>
    </visual>
    <inertial>
      <origin rpy="0 0 0" xyz="0 0 0.025"/>
      <mass value="1"/>
      <inertia ixx="1.0" ixy="0.0" ixz="0.0" iyy="1.0" iyz="0.0" izz="1.0"/>
    </inertial>
  </link>
  <joint name="mic_fixed_joint" type="fixed">
    <parent link="mic_stand_link"/>
    <child link="mic"/>
    <origin rpy="0 0.78 0" xyz="0.0 0 0.05"/>
    <axis xyz="0 1 0"/>
  </joint>

  <link name="mic">
    <collision>
      <origin rpy="0 0 0" xyz="0 0 0.05"/>
      <geometry>
        <cylinder radius="0.01" length="0.18"/>
      </geometry>
    </collision>
    <visual>
      <origin rpy="0 0 0" xyz="0 0 0.05"/>
      <geometry>
        <cylinder radius="0.01" length="0.18"/>
      </geometry>
      <material name="black"/>
    </visual>
    <inertial>
      <origin rpy="0 0 0" xyz="0 0 0.05"/>
      <mass value="1"/>
      <inertia ixx="1.0" ixy="0.0" ixz="0.0" iyy="1.0" iyz="0.0" izz="1.0"/>
    </inertial>
  </link>

  <!-- Board_Base -->
  <joint name="board_base_joint" type="fixed">
    <parent link="base_mic_placed_link"/>
    <child link="board_base"/>
    <origin rpy="0 0 0" xyz="0.07 0 0.024"/>
    <axis xyz="0 1 0"/>
  </joint>

  <link name="board_base">
    <collision>
      <origin rpy="0 0 0" xyz="0 0 0"/>
      <geometry>
        <box size="0.096 0.062 0.028"/>
      </geometry>
    </collision>
    <visual>
      <origin rpy="0 0 0" xyz="0 0 0"/>
      <geometry>
        <box size="0.096 0.062 0.028"/>
      </geometry>
      <material name="white"/>
    </visual>
    <inertial>
      <origin rpy="0 0 0" xyz="0 0 0"/>
      <mass value="1"/>
      <inertia ixx="1.0" ixy="0.0" ixz="0.0" iyy="1.0" iyz="0.0" izz="1.0"/>
    </inertial>
  </link>
  <joint name="dev_board_joint" type="fixed">
    <parent link="board_base"/>
    <child link="dev_board"/>
    <origin rpy="0 0 0" xyz="0 0 0.015"/>
    <axis xyz="0 1 0"/>
  </joint>

  <!-- MATRIX_Creator -->
  <link name="dev_board">
    <collision>
      <origin rpy="0 0 0" xyz="0 0 0"/>
      <geometry>
        <cylinder radius="0.054" length="0.002"/>
      </geometry>
    </collision>
    <visual>
      <origin rpy="0 0 0" xyz="0 0 0"/>
      <geometry>
        <cylinder radius="0.054" length="0.002"/>
      </geometry>
      <material name="blue"/>
    </visual>
    <inertial>
      <origin rpy="0 0 0" xyz="0 0 0"/>
      <mass value="1"/>
      <inertia ixx="1.0" ixy="0.0" ixz="0.0" iyy="1.0" iyz="0.0" izz="1.0"/>
    </inertial>
  </link>
  <joint name="sensor_joint" type="fixed">
    <parent link="dev_board"/>
    <child link="sensor"/>
    <origin rpy="0 0 0" xyz="0 0 0.0001"/>
    <axis xyz="0 1 0"/>
  </joint>

  <!-- Sensor -->
  <link name="sensor">
    <collision>
      <origin rpy="0 0 0" xyz="0 0 0"/>
      <geometry>
        <box size="0.012 0.012 0.002"/>
      </geometry>
    </collision>
    <visual>
      <origin rpy="0 0 0" xyz="0 0 0"/>
      <geometry>
        <box size="0.012 0.012 0.002"/>
      </geometry>
      <material name="white"/>
    </visual>
    <inertial>
      <origin rpy="0 0 0" xyz="0 0 0"/>
      <mass value="1"/>
      <inertia ixx="1.0" ixy="0.0" ixz="0.0" iyy="1.0" iyz="0.0" izz="1.0"/>
    </inertial>
  </link>

  <!-- rgb_link -->
  <link name="rgb_link"/>
  <joint name="xtion_joint5" type="fixed">
    <parent link="xtion"/>
    <child link="rgb_link"/>
    <origin rpy="-1.57 0 -1.57" xyz="0.02 0.0205 0.0375"/>
    <axis xyz="0 0 1"/>
    <limit effort="30" lower="-3.14" upper="3.14" velocity="1.571"/>
  </joint>


  <!-- depth_link -->
  <link name="depth_link"/>
  <joint name="xtion_joint6" type="fixed">
    <parent link="xtion"/>
    <child link="depth_link"/>
    <origin rpy="-1.57 0 -1.57" xyz="0.02 0.0475 0.0375"/>
    <axis xyz="0 0 1"/>
    <limit effort="30" lower="-3.14" upper="3.14" velocity="1.571"/>
  </joint>

  <transmission name="arm_roll_joint_transmission">
		<type>transmission_interface/SimpleTransmission</type>
		<joint name="arm_roll_joint">
			<hardwareInterface>hardware_interface/PositionJointInterface</hardwareInterface>
		</joint>
		<actuator name="arm_roll_joint_actuator">
			<hardwareInterface>hardware_interface/PositionJointInterface</hardwareInterface>
			<mechanicalReduction>1</mechanicalReduction>
		</actuator>
	</transmission>

	<transmission name="arm_flex_joint_transmission">
		<type>transmission_interface/SimpleTransmission</type>
		<joint name="arm_flex_joint">
			<hardwareInterface>hardware_interface/PositionJointInterface</hardwareInterface>
		</joint>
		<actuator name="arm_flex_joint_actuator">
			<hardwareInterface>hardware_interface/PositionJointInterface</hardwareInterface>
			<mechanicalReduction>1</mechanicalReduction>
		</actuator>
	</transmission>

	<transmission name="elbow_flex_joint_transmission">
		<type>transmission_interface/SimpleTransmission</type>
		<joint name="elbow_flex_joint">
			<hardwareInterface>hardware_interface/PositionJointInterface</hardwareInterface>
		</joint>
		<actuator name="elbow_flex_joint_actuator">
			<hardwareInterface>hardware_interface/PositionJointInterface</hardwareInterface>
			<mechanicalReduction>1</mechanicalReduction>
		</actuator>
	</transmission>

  <transmission name="wrist_flex_joint_transmission">
		<type>transmission_interface/SimpleTransmission</type>
		<joint name="wrist_flex_joint">
			<hardwareInterface>hardware_interface/PositionJointInterface</hardwareInterface>
		</joint>
		<actuator name="wrist_flex_joint_actuator">
			<hardwareInterface>hardware_interface/PositionJointInterface</hardwareInterface>
			<mechanicalReduction>1</mechanicalReduction>
		</actuator>
	</transmission>

	<transmission name="hand_motor_joint_transmission">
		<type>transmission_interface/SimpleTransmission</type>
		<joint name="hand_motor_joint">
			<hardwareInterface>hardware_interface/PositionJointInterface</hardwareInterface>
		</joint>
		<actuator name="hand_motor_joint_actuator">
			<hardwareInterface>hardware_interface/PositionJointInterface</hardwareInterface>
			<mechanicalReduction>1</mechanicalReduction>
		</actuator>
	</transmission>
  
  <!-- gazebo_setting -->
  <!--gazebo>
    <plugin name="gazebo_ros_control" filename="libgazebo_ros_control.so">
      <robotNamespace>/sobit_education</robotNamespace>
      <robotSimType>gazebo_ros_control/DefaultRobotHWSim</robotSimType>
      <legacyModeNS>true</legacyModeNS>
    </plugin>
  </gazebo-->
</robot>
