<?xml version="1.0" ?>
<!-- =================================================================================== -->
<!-- |    This document was autogenerated by xacro from kobuki_hexagons_asus_xtion_pro_offset_education_turtolebot.urdf.xacro | -->
<!-- |    EDITING THIS FILE BY HAND IS NOT RECOMMENDED                                 | -->
<!-- =================================================================================== -->
<robot name="turtlebot" xmlns:xacro="http://ros.org/wiki/xacro">
  <!-- 
    These properties must be observed by any machine
    that wants to be defined as a turtlebot. Refer
    to the REP for more details.
    
    http://www.ros.org/reps/rep-0119.html
   -->
  <!-- urg -->
  <joint name="laser" type="fixed">
    <origin rpy="0 0 0" xyz="0.205 0.0 0.01"/>
    <parent link="base_link"/>
    <child link="base_laser_link"/>
    <origin rpy="0 0 0" xyz="0.13525 0.0 0.034"/>
    <axis xyz="0 0 1"/>
    <limit effort="30" lower="-3.14" upper="3.14" velocity="1.571"/>
  </joint>
  <link name="base_laser_link">
    <visual>
      <geometry>
        <mesh filename="package://sobit_education_description/model/dae/UST-20LX.dae"/>
      </geometry>
      <material name="Black"/>
    </visual>
    <inertial>
      <mass value="0.000001"/>
      <origin xyz="0 0 0"/>
      <inertia ixx="0.0001" ixy="0.0" ixz="0.0" iyy="0.0001" iyz="0.0" izz="0.0001"/>
    </inertial>
  </link>
  <material name="red">
    <color rgba="1.0 0.0 0.0 1.0"/>
  </material>
  <material name="green">
    <color rgba="0.0 1.0 0.0 1.0"/>
  </material>
  <material name="blue">
    <color rgba="0.0 0.0 1.0 1.0"/>
  </material>
  <material name="black">
    <color rgba="0.0 0.0 0.0 1.0"/>
  </material>
  <material name="white">
    <color rgba="0.87 0.90 0.87 1.0"/>
  </material>
  <material name="orange">
    <color rgba="1.0 0.4 0.0 1.0"/>
  </material>
  <joint name="fixed" type="fixed">
    <parent link="plate_top_link"/>
    <child link="link1"/>
    <origin rpy="0 0 0" xyz="0.0 0.0 0.0"/>
    <axis xyz="0 0 1"/>
    <limit effort="30" lower="-3.14" upper="3.14" velocity="1.571"/>
  </joint>
  <!-- Link 1 -->
  <link name="link1">
    <collision>
      <geometry>
        <mesh filename="package://sobit_education_description/model/dae/Manipulator_X4_Joint1_fix.dae"/>
      </geometry>
    </collision>
    <visual>
      <origin rpy="0 0 0" xyz="0.0845 0 0"/>
      <geometry>
        <mesh filename="package://sobit_education_description/model/dae/Manipulator_X4_Joint1_fix.dae"/>
      </geometry>
      <material name="black"/>
    </visual>
    <inertial>
      <origin rpy="0 0 0" xyz="0.0845 0 0"/>
      <mass value="0.08"/>
      <inertia ixx="1.0" ixy="0.0" ixz="0.0" iyy="1.0" iyz="0.0" izz="1.0"/>
    </inertial>
  </link>
  <joint name="joint1" type="revolute">
    <parent link="link1"/>
    <child link="link2"/>
    <origin rpy="0 0 0" xyz="0.13525 0.0 0.034"/>
    <axis xyz="0 0 1"/>
    <limit effort="30" lower="-3.14" upper="3.14" velocity="1.571"/>
  </joint>
  <!-- Link 2 -->
  <link name="link2">
    <collision>
      <geometry>
        <mesh filename="package://sobit_education_description/model/dae/Manipulator_X4_Joint2_fix.dae"/>
      </geometry>
    </collision>
    <visual>
      <origin rpy="0 0 0" xyz="0 0 0.0"/>
      <geometry>
        <mesh filename="package://sobit_education_description/model/dae/Manipulator_X4_Joint2_fix.dae"/>
      </geometry>
      <material name="black"/>
    </visual>
    <inertial>
      <origin rpy="0 0 0" xyz="0 0 0.0"/>
      <mass value="0.08"/>
      <inertia ixx="1.0" ixy="0.0" ixz="0.0" iyy="1.0" iyz="0.0" izz="1.0"/>
    </inertial>
  </link>
  <joint name="joint2" type="revolute">
    <parent link="link2"/>
    <child link="link3"/>
    <origin rpy="0 0 0" xyz="0.0 0.0 0.0421"/>
    <axis xyz="0 1 0"/>
    <limit effort="30" lower="0" upper="1.57" velocity="1.571"/>
  </joint>
  <!-- Link 3 -->
  <link name="link3"/>
  <joint name="joint3" type="revolute">
    <parent link="link3"/>
    <child link="link4"/>
    <origin rpy="0 0 0" xyz="0 0 0.0"/>
    <axis xyz="0 0 1"/>
    <limit effort="30" lower="-0.1" upper="0.1" velocity="1.571"/>
  </joint>
  <!-- Link 4 -->
  <link name="link4">
    <collision>
      <geometry>
        <mesh filename="package://sobit_education_description/model/dae/Manipulator_X4_Joint3_fix.dae"/>
      </geometry>
    </collision>
    <visual>
      <origin rpy="0 0 0" xyz="0 0 0"/>
      <geometry>
        <mesh filename="package://sobit_education_description/model/dae/Manipulator_X4_Joint3_fix.dae"/>
      </geometry>
      <material name="black"/>
    </visual>
    <inertial>
      <origin rpy="0 0 0" xyz="0 0 0"/>
      <mass value="0.08"/>
      <inertia ixx="1.0" ixy="0.0" ixz="0.0" iyy="1.0" iyz="0.0" izz="1.0"/>
    </inertial>
  </link>
  <joint name="joint4" type="revolute">
    <parent link="link4"/>
    <child link="link5"/>
    <origin rpy="0 1.57 0" xyz="0.024 0.0 0.148"/>
    <axis xyz="0 1 0"/>
    <limit effort="30" lower="-1.57" upper="1.4155" velocity="1.571"/>
  </joint>
  <!-- Link 5 -->
  <link name="link5"/>
  <joint name="joint5" type="revolute">
    <parent link="link5"/>
    <child link="link6"/>
    <origin rpy="0 0 0" xyz="0 0 0.0"/>
    <axis xyz="0 0 1"/>
    <limit effort="30" lower="-0.1" upper="0.1" velocity="1.571"/>
  </joint>
  <!-- Link 6 -->
  <link name="link6">
    <collision>
      <geometry>
        <mesh filename="package://sobit_education_description/model/dae/Manipulator_X4_Joint4_fix.dae"/>
      </geometry>
    </collision>
    <visual>
      <origin rpy="0 0 0" xyz="0 0 0"/>
      <geometry>
        <mesh filename="package://sobit_education_description/model/dae/Manipulator_X4_Joint4_fix.dae"/>
      </geometry>
      <material name="black"/>
    </visual>
    <inertial>
      <origin rpy="0 0 0" xyz="0 0 0"/>
      <mass value="0.08"/>
      <inertia ixx="1.0" ixy="0.0" ixz="0.0" iyy="1.0" iyz="0.0" izz="1.0"/>
    </inertial>
  </link>
  <!-- Link 7/8 (end effector)-->
  <link name="link7">
    <collision>
      <geometry>
        <mesh filename="package://sobit_education_description/model/dae/Manipulator_X4_Gripper_fix.dae"/>
      </geometry>
    </collision>
    <visual>
      <origin rpy="0 0 0" xyz="0 0 0"/>
      <geometry>
        <mesh filename="package://sobit_education_description/model/dae/Manipulator_X4_Gripper_fix.dae"/>
      </geometry>
      <material name="black"/>
    </visual>
    <inertial>
      <origin rpy="0 0 0" xyz="0 0 0"/>
      <mass value="0.08"/>
      <inertia ixx="1.0" ixy="0.0" ixz="0.0" iyy="1.0" iyz="0.0" izz="1.0"/>
    </inertial>
  </link>
  <joint name="joint6" type="revolute">
    <parent link="link6"/>
    <child link="link7"/>
    <origin rpy="0 0 0" xyz="0.0 0.0 0.15"/>
    <axis xyz="0 1 0"/>
    <limit effort="30" lower="-1.57" upper="1.57" velocity="1.571"/>
  </joint>
  <!-- marker -->
  <link name="link8"/>
  <joint name="joint7" type="revolute">
    <parent link="link7"/>
    <child link="link8"/>
    <origin rpy="0 0 0" xyz="0.0 0.0 0.13225"/>
    <axis xyz="1 0 0"/>
    <limit effort="30" lower="-2.617" upper="2.617" velocity="1.571"/>
  </joint>
  <joint name="joint8" type="revolute">
    <parent link="link7"/>
    <child link="link9"/>
    <origin rpy="0.78 0 0" xyz="0.0 0.01 0.04225"/>
    <axis xyz="1 0 0"/>
    <limit effort="1" lower="-1.57" upper="0.0" velocity="1"/>
  </joint>
  <joint name="joint9" type="revolute">
    <parent link="link7"/>
    <child link="link10"/>
    <origin rpy="-0.78 0 0" xyz="0.0 -0.01 0.04225"/>
    <axis xyz="1 0 0"/>
    <limit effort="1" lower="0" upper="1.57" velocity="1"/>
  </joint>
  <link name="link9">
    <collision>
      <geometry>
        <mesh filename="package://sobit_education_description/model/dae/ManipulatorX4_Finger_right.dae"/>
      </geometry>
    </collision>
    <visual>
      <origin rpy="0 0 0" xyz="0 0 0"/>
      <geometry>
        <mesh filename="package://sobit_education_description/model/dae/ManipulatorX4_Finger_right.dae"/>
      </geometry>
      <material name="black">
        <color rgba="0.0 0.0 0.0 1.0"/>
      </material>
    </visual>
    <inertial>
      <origin rpy="0 0 0" xyz="0 0 0"/>
      <mass value="0.08"/>
      <inertia ixx="1.0" ixy="0.0" ixz="0.0" iyy="1.0" iyz="0.0" izz="1.0"/>
    </inertial>
  </link>
  <!--scale="10.001 10.001 10.001-->
  <link name="link10">
    <collision>
      <geometry>
        <mesh filename="package://sobit_education_description/model/dae/ManipulatorX4_Finger_right.dae"/>
      </geometry>
    </collision>
    <visual>
      <origin rpy="0 0 3.14" xyz="0 0 0"/>
      <geometry>
        <mesh filename="package://sobit_education_description/model/dae/ManipulatorX4_Finger_right.dae"/>
      </geometry>
      <material name="black">
        <color rgba="0.0 0.0 0.0 1.0"/>
      </material>
    </visual>
    <inertial>
      <origin rpy="0 0 3.14" xyz="0 0 0"/>
      <mass value="0.08"/>
      <inertia ixx="1.0" ixy="0.0" ixz="0.0" iyy="1.0" iyz="0.0" izz="1.0"/>
    </inertial>
  </link>
  <!-- xtion -->
  <joint name="xtion_fixed" type="fixed">
    <parent link="plate_top_link"/>
    <child link="xtion_link1"/>
    <origin rpy="0 0 0" xyz="0 0.0 0.0"/>
    <axis xyz="0 0 1"/>
    <limit effort="30" lower="-3.14" upper="3.14" velocity="1.571"/>
  </joint>
  <!-- Link 1 -->
  <link name="xtion_link1">
    <collision>
      <origin rpy="0 0 0" xyz="-0.062 0 0.303"/>
      <geometry>
        <box size="0.02 0.02 0.6"/>
      </geometry>
    </collision>
    <visual>
      <origin rpy="0 0 0" xyz="-0.062 0 0.303"/>
      <geometry>
        <box size="0.02 0.02 0.6"/>
      </geometry>
      <material name="white"/>
    </visual>
    <inertial>
      <origin rpy="0 0 0" xyz="-0.062 0 0.303"/>
      <mass value="1"/>
      <inertia ixx="1.0" ixy="0.0" ixz="0.0" iyy="1.0" iyz="0.0" izz="1.0"/>
    </inertial>
  </link>
  <joint name="xtion_joint1" type="fixed">
    <parent link="xtion_link1"/>
    <child link="xtion_link2"/>
    <origin rpy="0 0 0" xyz="-0.062 0 0.373"/>
    <axis xyz="0 0 1"/>
    <limit effort="30" lower="-3.14" upper="3.14" velocity="1.571"/>
  </joint>
  <joint name="mic_joint1" type="fixed">
    <parent link="xtion_link1"/>
    <child link="mic_link"/>
    <origin rpy="0 0 0" xyz="-0.062 0 0.613"/>
    <axis xyz="0 1 0"/>
  </joint>
  <!-- Link 2 -->
  <link name="xtion_link2">
    <collision>
      <origin rpy="0 0 0" xyz="0.08 0 0"/>
      <geometry>
        <box size="0.14 0.02 0.02"/>
      </geometry>
    </collision>
    <visual>
      <origin rpy="0 0 0" xyz="0.08 0 0"/>
      <geometry>
        <box size="0.14 0.02 0.02"/>
      </geometry>
      <material name="white"/>
    </visual>
    <inertial>
      <origin rpy="0 0 0" xyz="0.08 0 0.0"/>
      <mass value="1"/>
      <inertia ixx="1.0" ixy="0.0" ixz="0.0" iyy="1.0" iyz="0.0" izz="1.0"/>
    </inertial>
  </link>
  <joint name="xtion_joint2" type="fixed">
    <parent link="xtion_link2"/>
    <child link="xtion_link3"/>
    <origin rpy="0 0 0" xyz="0.14 0 0.0"/>
    <axis xyz="0 0 1"/>
    <limit effort="30" lower="-3.14" upper="3.14" velocity="1.571"/>
  </joint>
  <!-- Link 3 -->
  <link name="xtion_link3">
    <collision>
      <origin rpy="0 0 0" xyz="0.0265 0 0.0155"/>
      <geometry>
        <box size="0.033 0.033 0.051"/>
      </geometry>
    </collision>
    <visual>
      <origin rpy="0 0 0" xyz="0.0265 0 0.0155"/>
      <geometry>
        <box size="0.033 0.033 0.051"/>
      </geometry>
      <material name="black"/>
    </visual>
    <inertial>
      <origin rpy="0 0 0" xyz="0.0265 0 0.0155"/>
      <mass value="1"/>
      <inertia ixx="1.0" ixy="0.0" ixz="0.0" iyy="1.0" iyz="0.0" izz="1.0"/>
    </inertial>
  </link>
  <joint name="xtion_joint3" type="revolute">
    <parent link="xtion_link3"/>
    <child link="xtion_link4"/>
    <origin rpy="0 1.57 0" xyz="0.0265 0 0.03"/>
    <axis xyz="0 1 0"/>
    <limit effort="30" lower="-3.14" upper="0" velocity="1.571"/>
  </joint>
  <!-- Link 4 -->
  <link name="xtion_link4">
    <collision>
      <origin rpy="0 0 0" xyz="0.0 0 0.014"/>
      <geometry>
        <box size="0.02 0.041 0.028"/>
      </geometry>
    </collision>
    <visual>
      <origin rpy="0 0 0" xyz="0.0 0 0.014"/>
      <geometry>
        <box size="0.02 0.041 0.028"/>
      </geometry>
      <material name="black"/>
    </visual>
    <inertial>
      <origin rpy="0 0 0" xyz="0.0 0 0.0"/>
      <mass value="1"/>
      <inertia ixx="1.0" ixy="0.0" ixz="0.0" iyy="1.0" iyz="0.0" izz="1.0"/>
    </inertial>
  </link>
  <joint name="xtion_joint4" type="fixed">
    <parent link="xtion_link4"/>
    <child link="xtion"/>
    <origin rpy="0 0 0" xyz="0.0 0 0.0"/>
    <axis xyz="0 1 0"/>
    <limit effort="30" lower="-0.17" upper="1.57" velocity="1.571"/>
  </joint>
  <link name="xtion">
    <visual>
      <origin rpy="0 0 0" xyz="-0.0 0.0 0.0405"/>
      <geometry>
        <mesh filename="package://turtlebot_description/meshes/sensors/xtion_pro_camera.dae"/>
      </geometry>
    </visual>
    <collision>
      <origin rpy="0 0 0" xyz="0.0 0.0 0.0405"/>
      <geometry>
        <box size="0.0730 0.2760 0.0720"/>
      </geometry>
    </collision>
    <inertial>
      <mass value="0.170"/>
      <origin xyz="0 0 0"/>
      <inertia ixx="0.001152600" ixy="0.0" ixz="0.0" iyy="0.000148934" iyz="0.0" izz="0.001154654"/>
    </inertial>
  </link>
  <!-- mic_link -->
  <link name="mic_link">
    <collision>
      <origin rpy="0 0 0" xyz="0.09 0 0.0"/>
      <geometry>
        <box size="0.2 0.02 0.02"/>
      </geometry>
    </collision>
    <visual>
      <origin rpy="0 0 0" xyz="0.09 0 0.0"/>
      <geometry>
        <box size="0.2 0.02 0.02"/>
      </geometry>
      <material name="white"/>
    </visual>
    <inertial>
      <origin rpy="0 0 0" xyz="0.0 0 0.613"/>
      <mass value="1"/>
      <inertia ixx="1.0" ixy="0.0" ixz="0.0" iyy="1.0" iyz="0.0" izz="1.0"/>
    </inertial>
  </link>
  <joint name="mic_joint2" type="fixed">
    <parent link="mic_link"/>
    <child link="mic_stand"/>
    <origin rpy="0 0 0" xyz="0.175 0 0.01"/>
    <axis xyz="0 1 0"/>
  </joint>
  <joint name="board_base_joint" type="fixed">
    <parent link="mic_link"/>
    <child link="board_base"/>
    <origin rpy="0 0 0" xyz="0.07 0 0.024"/>
    <axis xyz="0 1 0"/>
  </joint>
  <!-- Board_Base -->
  <link name="board_base">
    <collision>
      <origin rpy="0 0 0" xyz="0 0 0"/>
      <geometry>
        <box size="0.096 0.062 0.028"/>
      </geometry>
    </collision>
    <visual>
      <origin rpy="0 0 0" xyz="0 0 0"/>
      <geometry>
        <box size="0.096 0.062 0.028"/>
      </geometry>
      <material name="white"/>
    </visual>
    <inertial>
      <origin rpy="0 0 0" xyz="0 0 0"/>
      <mass value="1"/>
      <inertia ixx="1.0" ixy="0.0" ixz="0.0" iyy="1.0" iyz="0.0" izz="1.0"/>
    </inertial>
  </link>
  <joint name="board_joint" type="fixed">
    <parent link="board_base"/>
    <child link="dev_board"/>
    <origin rpy="0 0 0" xyz="0 0 0.015"/>
    <axis xyz="0 1 0"/>
  </joint>
  <!-- MATRIX_Creator -->
  <link name="dev_board">
    <collision>
      <origin rpy="0 0 0" xyz="0 0 0"/>
      <geometry>
        <cylinder length="0.002" radius="0.054"/>
      </geometry>
    </collision>
    <visual>
      <origin rpy="0 0 0" xyz="0 0 0"/>
      <geometry>
        <cylinder length="0.002" radius="0.054"/>
      </geometry>
      <material name="blue"/>
    </visual>
    <inertial>
      <origin rpy="0 0 0" xyz="0 0 0"/>
      <mass value="1"/>
      <inertia ixx="1.0" ixy="0.0" ixz="0.0" iyy="1.0" iyz="0.0" izz="1.0"/>
    </inertial>
  </link>
  <joint name="sensor_joint" type="fixed">
    <parent link="dev_board"/>
    <child link="sensor"/>
    <origin rpy="0 0 0" xyz="0 0 0.0001"/>
    <axis xyz="0 1 0"/>
  </joint>
  <!-- Sensor -->
  <link name="sensor">
    <collision>
      <origin rpy="0 0 0" xyz="0 0 0"/>
      <geometry>
        <box size="0.012 0.012 0.002"/>
      </geometry>
    </collision>
    <visual>
      <origin rpy="0 0 0" xyz="0 0 0"/>
      <geometry>
        <box size="0.012 0.012 0.002"/>
      </geometry>
      <material name="white"/>
    </visual>
    <inertial>
      <origin rpy="0 0 0" xyz="0 0 0"/>
      <mass value="1"/>
      <inertia ixx="1.0" ixy="0.0" ixz="0.0" iyy="1.0" iyz="0.0" izz="1.0"/>
    </inertial>
  </link>
  <!-- mic_stand -->
  <link name="mic_stand">
    <collision>
      <origin rpy="0 0 0" xyz="0 0 0.025"/>
      <geometry>
        <cylinder length="0.05" radius="0.015"/>
      </geometry>
    </collision>
    <visual>
      <origin rpy="0 0 0" xyz="0 0 0.025"/>
      <geometry>
        <cylinder length="0.05" radius="0.015"/>
      </geometry>
      <material name="black"/>
    </visual>
    <inertial>
      <origin rpy="0 0 0" xyz="0 0 0.025"/>
      <mass value="1"/>
      <inertia ixx="1.0" ixy="0.0" ixz="0.0" iyy="1.0" iyz="0.0" izz="1.0"/>
    </inertial>
  </link>
  <joint name="mic_joint3" type="fixed">
    <parent link="mic_stand"/>
    <child link="mic"/>
    <origin rpy="0 0.78 0" xyz="0.0 0 0.05"/>
    <axis xyz="0 1 0"/>
  </joint>
  <!-- mic -->
  <link name="mic">
    <collision>
      <origin rpy="0 0 0" xyz="0 0 0.05"/>
      <geometry>
        <cylinder length="0.18" radius="0.01"/>
      </geometry>
    </collision>
    <visual>
      <origin rpy="0 0 0" xyz="0 0 0.05"/>
      <geometry>
        <cylinder length="0.18" radius="0.01"/>
      </geometry>
      <material name="black"/>
    </visual>
    <inertial>
      <origin rpy="0 0 0" xyz="0 0 0.05"/>
      <mass value="1"/>
      <inertia ixx="1.0" ixy="0.0" ixz="0.0" iyy="1.0" iyz="0.0" izz="1.0"/>
    </inertial>
  </link>
  <!-- rgb_link -->
  <link name="rgb_link"/>
  <joint name="xtion_joint5" type="fixed">
    <parent link="xtion"/>
    <child link="rgb_link"/>
    <origin rpy="-1.57 0 -1.57" xyz="0 0.0205 0"/>
    <axis xyz="0 0 1"/>
    <limit effort="30" lower="-3.14" upper="3.14" velocity="1.571"/>
  </joint>
  <!-- depth_link -->
  <link name="depth_link"/>
  <joint name="xtion_joint6" type="fixed">
    <parent link="xtion"/>
    <child link="depth_link"/>
    <origin rpy="-1.57 0 -1.57" xyz="0 0.0475 0"/>
    <axis xyz="0 0 1"/>
    <limit effort="30" lower="-3.14" upper="3.14" velocity="1.571"/>
  </joint>
  <!-- xacro:include filename="$(find turtlebot_edu)/model/urdf/sensors/asus_xtion_pro_offset_fix.urdf.xacro"/ -->
  <link name="base_footprint"/>
  <!--
       Base link is set at the bottom of the base mould.
       This is done to be compatible with the way base link
       was configured for turtlebot 1. Refer to

       https://github.com/turtlebot/turtlebot/issues/40

       To put the base link at the more oft used wheel
       axis, set the z-distance from the base_footprint
       to 0.352.
      -->
  <joint name="base_joint" type="fixed">
    <origin rpy="0 0 0" xyz="0 0 0.0102"/>
    <parent link="base_footprint"/>
    <child link="base_link"/>
  </joint>
  <link name="base_link">
    <visual>
      <geometry>
        <!-- new mesh -->
        <mesh filename="package://kobuki_description/meshes/main_body.dae"/>
      </geometry>
      <origin rpy="0 0 0" xyz="0.001 0 0.05199"/>
    </visual>
    <collision name="base">
      <geometry>
        <cylinder length="0.10938" radius="0.178"/>
      </geometry>
      <origin rpy="0 0 0" xyz="0.0 0 0.05949"/>
    </collision>
    <inertial>
      <!-- COM experimentally determined -->
      <origin xyz="0.01 0 0"/>
      <mass value="2.4"/>
      <!-- 2.4/2.6 kg for small/big battery pack -->
      <!-- Kobuki's inertia tensor is approximated by a cylinder with homogeneous mass distribution
             More details: http://en.wikipedia.org/wiki/List_of_moment_of_inertia_tensors
             m = 2.4 kg; h = 0.09 m; r = 0.175 m
             ixx = 1/12 * m * (3 * r^2 + h^2)
             iyy = 1/12 * m * (3 * r^2 + h^2)
             izz = 1/2 * m * r^2
          -->
      <inertia ixx="0.019995" ixy="0.0" ixz="0.0" iyy="0.019995" iyz="0.0" izz="0.03675"/>
    </inertial>
  </link>
  <joint name="wheel_left_joint" type="continuous">
    <parent link="base_link"/>
    <child link="wheel_left_link"/>
    <origin rpy="-1.57079632679 0 0" xyz="0.00 0.115 0.0250"/>
    <axis xyz="0 0 1"/>
  </joint>
  <link name="wheel_left_link">
    <visual>
      <geometry>
        <mesh filename="package://kobuki_description/meshes/wheel.dae"/>
      </geometry>
      <origin rpy="0 0 0" xyz="0 0 0"/>
    </visual>
    <collision>
      <geometry>
        <cylinder length="0.0206" radius="0.0352"/>
      </geometry>
      <origin rpy="0 0 0" xyz="0 0 0"/>
    </collision>
    <inertial>
      <mass value="0.01"/>
      <origin xyz="0 0 0"/>
      <inertia ixx="0.001" ixy="0.0" ixz="0.0" iyy="0.001" iyz="0.0" izz="0.001"/>
    </inertial>
  </link>
  <joint name="wheel_right_joint" type="continuous">
    <parent link="base_link"/>
    <child link="wheel_right_link"/>
    <origin rpy="-1.57079632679 0 0" xyz="0.00 -0.115 0.0250"/>
    <axis xyz="0 0 1"/>
  </joint>
  <link name="wheel_right_link">
    <visual>
      <geometry>
        <mesh filename="package://kobuki_description/meshes/wheel.dae"/>
      </geometry>
      <origin rpy="0 0 0" xyz="0 0 0"/>
    </visual>
    <collision>
      <geometry>
        <cylinder length="0.0206" radius="0.0350"/>
      </geometry>
      <origin rpy="0 0 0" xyz="0 0 0"/>
    </collision>
    <inertial>
      <mass value="0.01"/>
      <origin xyz="0 0 0"/>
      <inertia ixx="0.001" ixy="0.0" ixz="0.0" iyy="0.001" iyz="0.0" izz="0.001"/>
    </inertial>
  </link>
  <joint name="caster_front_joint" type="fixed">
    <parent link="base_link"/>
    <child link="caster_front_link"/>
    <origin rpy="-1.57079632679 0 0" xyz="0.115 0.0 0.007"/>
  </joint>
  <link name="caster_front_link">
    <collision>
      <geometry>
        <cylinder length="0.0176" radius="0.017"/>
      </geometry>
      <origin rpy="0 0 0" xyz="0 0 0"/>
    </collision>
    <inertial>
      <mass value="0.01"/>
      <origin xyz="0 0 0"/>
      <inertia ixx="0.001" ixy="0.0" ixz="0.0" iyy="0.001" iyz="0.0" izz="0.001"/>
    </inertial>
  </link>
  <joint name="caster_back_joint" type="fixed">
    <parent link="base_link"/>
    <child link="caster_back_link"/>
    <origin rpy="-1.57079632679 0 0" xyz="-0.135 0.0 0.009"/>
  </joint>
  <link name="caster_back_link">
    <collision>
      <geometry>
        <cylinder length="0.0176" radius="0.017"/>
      </geometry>
      <origin rpy="0 0 0" xyz="0 0 0"/>
    </collision>
    <inertial>
      <mass value="0.01"/>
      <origin xyz="0 0 0"/>
      <inertia ixx="0.001" ixy="0.0" ixz="0.0" iyy="0.001" iyz="0.0" izz="0.001"/>
    </inertial>
  </link>
  <!-- Kobuki's sensors -->
  <joint name="gyro_joint" type="fixed">
    <axis xyz="0 1 0"/>
    <origin rpy="0 0 0" xyz="0.056 0.062 0.0202"/>
    <parent link="base_link"/>
    <child link="gyro_link"/>
  </joint>
  <link name="gyro_link">
    <inertial>
      <mass value="0.001"/>
      <origin rpy="0 0 0" xyz="0 0 0"/>
      <inertia ixx="0.0001" ixy="0" ixz="0" iyy="0.000001" iyz="0" izz="0.0001"/>
    </inertial>
  </link>
  <joint name="cliff_sensor_left_joint" type="fixed">
    <origin rpy="0 1.57079632679 0" xyz="0.08734 0.13601 0.0214"/>
    <parent link="base_link"/>
    <child link="cliff_sensor_left_link"/>
  </joint>
  <link name="cliff_sensor_left_link">
    <inertial>
      <mass value="0.0001"/>
      <origin xyz="0 0 0"/>
      <inertia ixx="0.0001" ixy="0.0" ixz="0.0" iyy="0.0001" iyz="0.0" izz="0.0001"/>
    </inertial>
  </link>
  <joint name="cliff_sensor_right_joint" type="fixed">
    <origin rpy="0 1.57079632679 0" xyz="0.085 -0.13601 0.0214"/>
    <parent link="base_link"/>
    <child link="cliff_sensor_right_link"/>
  </joint>
  <link name="cliff_sensor_right_link">
    <inertial>
      <mass value="0.0001"/>
      <origin xyz="0 0 0"/>
      <inertia ixx="0.0001" ixy="0.0" ixz="0.0" iyy="0.0001" iyz="0.0" izz="0.0001"/>
    </inertial>
  </link>
  <joint name="cliff_sensor_front_joint" type="fixed">
    <origin rpy="0 1.57079632679 0" xyz="0.156 0.00 0.0214"/>
    <parent link="base_link"/>
    <child link="cliff_sensor_front_link"/>
  </joint>
  <link name="cliff_sensor_front_link">
    <inertial>
      <mass value="0.0001"/>
      <origin xyz="0 0 0"/>
      <inertia ixx="0.0001" ixy="0.0" ixz="0.0" iyy="0.0001" iyz="0.0" izz="0.0001"/>
    </inertial>
  </link>
  <gazebo reference="wheel_left_link">
    <mu1>1.0</mu1>
    <mu2>1.0</mu2>
    <kp>1000000.0</kp>
    <kd>100.0</kd>
    <minDepth>0.001</minDepth>
    <maxVel>1.0</maxVel>
  </gazebo>
  <gazebo reference="wheel_right_link">
    <mu1>1.0</mu1>
    <mu2>1.0</mu2>
    <kp>1000000.0</kp>
    <kd>100.0</kd>
    <minDepth>0.001</minDepth>
    <maxVel>1.0</maxVel>
  </gazebo>
  <gazebo reference="caster_front_link">
    <mu1>0.0</mu1>
    <mu2>0.0</mu2>
    <kp>1000000.0</kp>
    <kd>100.0</kd>
    <minDepth>0.001</minDepth>
    <maxVel>1.0</maxVel>
  </gazebo>
  <gazebo reference="caster_back_link">
    <mu1>0.0</mu1>
    <mu2>0.0</mu2>
    <kp>1000000.0</kp>
    <kd>100.0</kd>
    <minDepth>0.001</minDepth>
    <maxVel>1.0</maxVel>
  </gazebo>
  <gazebo reference="base_link">
    <mu1>0.3</mu1>
    <mu2>0.3</mu2>
    <sensor name="bumpers" type="contact">
      <always_on>1</always_on>
      <update_rate>50.0</update_rate>
      <visualize>true</visualize>
      <contact>
        <collision>base_footprint_fixed_joint_lump__base_collision</collision>
      </contact>
    </sensor>
  </gazebo>
  <gazebo reference="cliff_sensor_left_link">
    <sensor name="cliff_sensor_left" type="ray">
      <always_on>true</always_on>
      <update_rate>50</update_rate>
      <visualize>true</visualize>
      <ray>
        <scan>
          <horizontal>
            <samples>50</samples>
            <resolution>1.0</resolution>
            <min_angle>-0.0436</min_angle>
            <!-- -2.5 degree -->
            <max_angle>0.0436</max_angle>
            <!-- 2.5 degree -->
          </horizontal>
          <!--            Can't use vertical rays until this bug is resolved: -->
          <!--            https://bitbucket.org/osrf/gazebo/issue/509/vertical-sensor-doesnt-works -->
          <!-- 	          <vertical> -->
          <!-- 	            <samples>50</samples> -->
          <!-- 	            <resolution>1.0</resolution> -->
          <!-- 	            <min_angle>-0.0436</min_angle>  -2.5 degree -->
          <!-- 	            <max_angle>0.0436</max_angle> 2.5 degree -->
          <!-- 	          </vertical> -->
        </scan>
        <range>
          <min>0.01</min>
          <max>0.15</max>
          <resolution>1.0</resolution>
        </range>
      </ray>
    </sensor>
  </gazebo>
  <gazebo reference="cliff_sensor_right_link">
    <sensor name="cliff_sensor_right" type="ray">
      <always_on>true</always_on>
      <update_rate>50</update_rate>
      <visualize>true</visualize>
      <ray>
        <scan>
          <horizontal>
            <samples>50</samples>
            <resolution>1.0</resolution>
            <min_angle>-0.0436</min_angle>
            <!-- -2.5 degree -->
            <max_angle>0.0436</max_angle>
            <!-- 2.5 degree -->
          </horizontal>
          <!--            Can't use vertical rays until this bug is resolved: -->
          <!--            https://bitbucket.org/osrf/gazebo/issue/509/vertical-sensor-doesnt-works -->
          <!-- 	          <vertical> -->
          <!-- 	            <samples>50</samples> -->
          <!-- 	            <resolution>1.0</resolution> -->
          <!-- 	            <min_angle>-0.0436</min_angle>  -2.5 degree -->
          <!-- 	            <max_angle>0.0436</max_angle> 2.5 degree -->
          <!-- 	          </vertical> -->
        </scan>
        <range>
          <min>0.01</min>
          <max>0.15</max>
          <resolution>1.0</resolution>
        </range>
      </ray>
    </sensor>
  </gazebo>
  <gazebo reference="cliff_sensor_front_link">
    <sensor name="cliff_sensor_front" type="ray">
      <always_on>true</always_on>
      <update_rate>50</update_rate>
      <visualize>true</visualize>
      <ray>
        <scan>
          <horizontal>
            <samples>50</samples>
            <resolution>1.0</resolution>
            <min_angle>-0.0436</min_angle>
            <!-- -2.5 degree -->
            <max_angle>0.0436</max_angle>
            <!-- 2.5 degree -->
          </horizontal>
          <!-- 	          Can't use vertical rays until this bug is resolved: -->
          <!--            https://bitbucket.org/osrf/gazebo/issue/509/vertical-sensor-doesnt-works -->
          <!-- 	          <vertical> -->
          <!-- 	            <samples>50</samples> -->
          <!-- 	            <resolution>1.0</resolution> -->
          <!-- 	            <min_angle>-0.0436</min_angle>  -2.5 degree -->
          <!-- 	            <max_angle>0.0436</max_angle> 2.5 degree -->
          <!-- 	          </vertical> -->
        </scan>
        <range>
          <min>0.01</min>
          <max>0.15</max>
          <resolution>1.0</resolution>
        </range>
      </ray>
    </sensor>
  </gazebo>
  <gazebo reference="gyro_link">
    <sensor name="imu" type="imu">
      <always_on>true</always_on>
      <update_rate>50</update_rate>
      <visualize>false</visualize>
      <imu>
        <noise>
          <type>gaussian</type>
          <rate>
            <mean>0.0</mean>
            <stddev>1.96e-06</stddev>
            <!-- 0.25 x 0.25 (deg/s) -->
            <bias_mean>0.0</bias_mean>
            <bias_stddev>0.0</bias_stddev>
          </rate>
          <accel>
            <!-- not used in the plugin and real robot, hence using tutorial values -->
            <mean>0.0</mean>
            <stddev>1.7e-2</stddev>
            <bias_mean>0.1</bias_mean>
            <bias_stddev>0.001</bias_stddev>
          </accel>
        </noise>
      </imu>
    </sensor>
  </gazebo>
  <gazebo>
    <plugin filename="libgazebo_ros_kobuki.so" name="kobuki_controller">
      <publish_tf>1</publish_tf>
      <left_wheel_joint_name>wheel_left_joint</left_wheel_joint_name>
      <right_wheel_joint_name>wheel_right_joint</right_wheel_joint_name>
      <wheel_separation>.230</wheel_separation>
      <wheel_diameter>0.070</wheel_diameter>
      <torque>1.0</torque>
      <velocity_command_timeout>0.6</velocity_command_timeout>
      <cliff_sensor_left_name>cliff_sensor_left</cliff_sensor_left_name>
      <cliff_sensor_center_name>cliff_sensor_front</cliff_sensor_center_name>
      <cliff_sensor_right_name>cliff_sensor_right</cliff_sensor_right_name>
      <cliff_detection_threshold>0.04</cliff_detection_threshold>
      <bumper_name>bumpers</bumper_name>
      <imu_name>imu</imu_name>
    </plugin>
  </gazebo>
  <joint name="pole_bottom_0_joint" type="fixed">
    <origin rpy="0 0 0" xyz="0.12 0.082 0.1028"/>
    <parent link="base_link"/>
    <child link="pole_bottom_0_link"/>
    <origin rpy="0 0 0" xyz="0.13525 0.0 0.034"/>
    <axis xyz="0 0 1"/>
    <limit effort="30" lower="-3.14" upper="3.14" velocity="1.571"/>
  </joint>
  <link name="pole_bottom_0_link">
    <visual>
      <origin rpy="0 0 0" xyz="0 0 0"/>
      <geometry>
        <mesh filename="package://turtlebot_description/meshes/stacks/hexagons/pole_bottom.dae"/>
      </geometry>
    </visual>
    <collision>
      <origin rpy="0 0 0" xyz="0 0 0"/>
      <geometry>
        <cylinder length="0.0492" radius="0.006"/>
      </geometry>
    </collision>
    <inertial>
      <mass value="0.008"/>
      <origin rpy="0 0 0" xyz="0 0 0"/>
      <inertia ixx="0.000001686" ixy="0.0" ixz="0.0" iyy="0.000001686" iyz="0.0" izz="0.000000144"/>
    </inertial>
  </link>
  <joint name="pole_bottom_1_joint" type="fixed">
    <origin rpy="0 0 0" xyz="0.055 0.12 0.1028"/>
    <parent link="base_link"/>
    <child link="pole_bottom_1_link"/>
    <origin rpy="0 0 0" xyz="0.13525 0.0 0.034"/>
    <axis xyz="0 0 1"/>
    <limit effort="30" lower="-3.14" upper="3.14" velocity="1.571"/>
  </joint>
  <link name="pole_bottom_1_link">
    <visual>
      <origin rpy="0 0 0" xyz="0 0 0"/>
      <geometry>
        <mesh filename="package://turtlebot_description/meshes/stacks/hexagons/pole_bottom.dae"/>
      </geometry>
    </visual>
    <collision>
      <origin rpy="0 0 0" xyz="0 0 0"/>
      <geometry>
        <cylinder length="0.0492" radius="0.006"/>
      </geometry>
    </collision>
    <inertial>
      <mass value="0.008"/>
      <origin rpy="0 0 0" xyz="0 0 0"/>
      <inertia ixx="0.000001686" ixy="0.0" ixz="0.0" iyy="0.000001686" iyz="0.0" izz="0.000000144"/>
    </inertial>
  </link>
  <joint name="pole_bottom_2_joint" type="fixed">
    <origin rpy="0 0 0" xyz="-0.055 0.12 0.1028"/>
    <parent link="base_link"/>
    <child link="pole_bottom_2_link"/>
    <origin rpy="0 0 0" xyz="0.13525 0.0 0.034"/>
    <axis xyz="0 0 1"/>
    <limit effort="30" lower="-3.14" upper="3.14" velocity="1.571"/>
  </joint>
  <link name="pole_bottom_2_link">
    <visual>
      <origin rpy="0 0 0" xyz="0 0 0"/>
      <geometry>
        <mesh filename="package://turtlebot_description/meshes/stacks/hexagons/pole_bottom.dae"/>
      </geometry>
    </visual>
    <collision>
      <origin rpy="0 0 0" xyz="0 0 0"/>
      <geometry>
        <cylinder length="0.0492" radius="0.006"/>
      </geometry>
    </collision>
    <inertial>
      <mass value="0.008"/>
      <origin rpy="0 0 0" xyz="0 0 0"/>
      <inertia ixx="0.000001686" ixy="0.0" ixz="0.0" iyy="0.000001686" iyz="0.0" izz="0.000000144"/>
    </inertial>
  </link>
  <joint name="pole_bottom_3_joint" type="fixed">
    <origin rpy="0 0 0" xyz="0.12 -0.082 0.1028"/>
    <parent link="base_link"/>
    <child link="pole_bottom_3_link"/>
    <origin rpy="0 0 0" xyz="0.13525 0.0 0.034"/>
    <axis xyz="0 0 1"/>
    <limit effort="30" lower="-3.14" upper="3.14" velocity="1.571"/>
  </joint>
  <link name="pole_bottom_3_link">
    <visual>
      <origin rpy="0 0 0" xyz="0 0 0"/>
      <geometry>
        <mesh filename="package://turtlebot_description/meshes/stacks/hexagons/pole_bottom.dae"/>
      </geometry>
    </visual>
    <collision>
      <origin rpy="0 0 0" xyz="0 0 0"/>
      <geometry>
        <cylinder length="0.0492" radius="0.006"/>
      </geometry>
    </collision>
    <inertial>
      <mass value="0.008"/>
      <origin rpy="0 0 0" xyz="0 0 0"/>
      <inertia ixx="0.000001686" ixy="0.0" ixz="0.0" iyy="0.000001686" iyz="0.0" izz="0.000000144"/>
    </inertial>
  </link>
  <joint name="pole_bottom_4_joint" type="fixed">
    <origin rpy="0 0 0" xyz="0.055 -0.12 0.1028"/>
    <parent link="base_link"/>
    <child link="pole_bottom_4_link"/>
    <origin rpy="0 0 0" xyz="0.13525 0.0 0.034"/>
    <axis xyz="0 0 1"/>
    <limit effort="30" lower="-3.14" upper="3.14" velocity="1.571"/>
  </joint>
  <link name="pole_bottom_4_link">
    <visual>
      <origin rpy="0 0 0" xyz="0 0 0"/>
      <geometry>
        <mesh filename="package://turtlebot_description/meshes/stacks/hexagons/pole_bottom.dae"/>
      </geometry>
    </visual>
    <collision>
      <origin rpy="0 0 0" xyz="0 0 0"/>
      <geometry>
        <cylinder length="0.0492" radius="0.006"/>
      </geometry>
    </collision>
    <inertial>
      <mass value="0.008"/>
      <origin rpy="0 0 0" xyz="0 0 0"/>
      <inertia ixx="0.000001686" ixy="0.0" ixz="0.0" iyy="0.000001686" iyz="0.0" izz="0.000000144"/>
    </inertial>
  </link>
  <joint name="pole_bottom_5_joint" type="fixed">
    <origin rpy="0 0 0" xyz="-0.055 -0.12 0.1028"/>
    <parent link="base_link"/>
    <child link="pole_bottom_5_link"/>
    <origin rpy="0 0 0" xyz="0.13525 0.0 0.034"/>
    <axis xyz="0 0 1"/>
    <limit effort="30" lower="-3.14" upper="3.14" velocity="1.571"/>
  </joint>
  <link name="pole_bottom_5_link">
    <visual>
      <origin rpy="0 0 0" xyz="0 0 0"/>
      <geometry>
        <mesh filename="package://turtlebot_description/meshes/stacks/hexagons/pole_bottom.dae"/>
      </geometry>
    </visual>
    <collision>
      <origin rpy="0 0 0" xyz="0 0 0"/>
      <geometry>
        <cylinder length="0.0492" radius="0.006"/>
      </geometry>
    </collision>
    <inertial>
      <mass value="0.008"/>
      <origin rpy="0 0 0" xyz="0 0 0"/>
      <inertia ixx="0.000001686" ixy="0.0" ixz="0.0" iyy="0.000001686" iyz="0.0" izz="0.000000144"/>
    </inertial>
  </link>
  <joint name="pole_bottom_0_joint_add" type="fixed">
    <origin rpy="0 0 0" xyz="0.0381 0.1505 0.199"/>
    <parent link="base_link"/>
    <child link="pole_bottom_0_link_add"/>
    <origin rpy="0 0 0" xyz="0.13525 0.0 0.034"/>
    <axis xyz="0 0 1"/>
    <limit effort="30" lower="-3.14" upper="3.14" velocity="1.571"/>
  </joint>
  <link name="pole_bottom_0_link_add">
    <visual>
      <origin rpy="0 0 0" xyz="0 0 0"/>
      <geometry>
        <mesh filename="package://turtlebot_description/meshes/stacks/hexagons/pole_bottom.dae"/>
      </geometry>
    </visual>
    <collision>
      <origin rpy="0 0 0" xyz="0 0 0"/>
      <geometry>
        <cylinder length="0.0492" radius="0.006"/>
      </geometry>
    </collision>
    <inertial>
      <mass value="0.008"/>
      <origin rpy="0 0 0" xyz="0 0 0"/>
      <inertia ixx="0.000001686" ixy="0.0" ixz="0.0" iyy="0.000001686" iyz="0.0" izz="0.000000144"/>
    </inertial>
  </link>
  <joint name="pole_bottom_1_joint_add" type="fixed">
    <origin rpy="0 0 0" xyz="0.0381 -0.1505 0.199"/>
    <parent link="base_link"/>
    <child link="pole_bottom_1_link_add"/>
    <origin rpy="0 0 0" xyz="0.13525 0.0 0.034"/>
    <axis xyz="0 0 1"/>
    <limit effort="30" lower="-3.14" upper="3.14" velocity="1.571"/>
  </joint>
  <link name="pole_bottom_1_link_add">
    <visual>
      <origin rpy="0 0 0" xyz="0 0 0"/>
      <geometry>
        <mesh filename="package://turtlebot_description/meshes/stacks/hexagons/pole_bottom.dae"/>
      </geometry>
    </visual>
    <collision>
      <origin rpy="0 0 0" xyz="0 0 0"/>
      <geometry>
        <cylinder length="0.0492" radius="0.006"/>
      </geometry>
    </collision>
    <inertial>
      <mass value="0.008"/>
      <origin rpy="0 0 0" xyz="0 0 0"/>
      <inertia ixx="0.000001686" ixy="0.0" ixz="0.0" iyy="0.000001686" iyz="0.0" izz="0.000000144"/>
    </inertial>
  </link>
  <joint name="pole_bottom_2_joint_add" type="fixed">
    <origin rpy="0 0 0" xyz="-0.0381 0.1505 0.199"/>
    <parent link="base_link"/>
    <child link="pole_bottom_2_link_add"/>
    <origin rpy="0 0 0" xyz="0.13525 0.0 0.034"/>
    <axis xyz="0 0 1"/>
    <limit effort="30" lower="-3.14" upper="3.14" velocity="1.571"/>
  </joint>
  <link name="pole_bottom_2_link_add">
    <visual>
      <origin rpy="0 0 0" xyz="0 0 0"/>
      <geometry>
        <mesh filename="package://turtlebot_description/meshes/stacks/hexagons/pole_bottom.dae"/>
      </geometry>
    </visual>
    <collision>
      <origin rpy="0 0 0" xyz="0 0 0"/>
      <geometry>
        <cylinder length="0.0492" radius="0.006"/>
      </geometry>
    </collision>
    <inertial>
      <mass value="0.008"/>
      <origin rpy="0 0 0" xyz="0 0 0"/>
      <inertia ixx="0.000001686" ixy="0.0" ixz="0.0" iyy="0.000001686" iyz="0.0" izz="0.000000144"/>
    </inertial>
  </link>
  <joint name="pole_bottom_3_joint_add" type="fixed">
    <origin rpy="0 0 0" xyz="-0.0381 -0.1505 0.199"/>
    <parent link="base_link"/>
    <child link="pole_bottom_3_link_add"/>
    <origin rpy="0 0 0" xyz="0.13525 0.0 0.034"/>
    <axis xyz="0 0 1"/>
    <limit effort="30" lower="-3.14" upper="3.14" velocity="1.571"/>
  </joint>
  <link name="pole_bottom_3_link_add">
    <visual>
      <origin rpy="0 0 0" xyz="0 0 0"/>
      <geometry>
        <mesh filename="package://turtlebot_description/meshes/stacks/hexagons/pole_bottom.dae"/>
      </geometry>
    </visual>
    <collision>
      <origin rpy="0 0 0" xyz="0 0 0"/>
      <geometry>
        <cylinder length="0.0492" radius="0.006"/>
      </geometry>
    </collision>
    <inertial>
      <mass value="0.008"/>
      <origin rpy="0 0 0" xyz="0 0 0"/>
      <inertia ixx="0.000001686" ixy="0.0" ixz="0.0" iyy="0.000001686" iyz="0.0" izz="0.000000144"/>
    </inertial>
  </link>
  <joint name="plate_bottom_joint" type="fixed">
    <origin rpy="0 0 0" xyz="0.02364 0.0 0.1306"/>
    <parent link="base_link"/>
    <child link="plate_bottom_link"/>
    <origin rpy="0 0 0" xyz="0.13525 0.0 0.034"/>
    <axis xyz="0 0 1"/>
    <limit effort="30" lower="-3.14" upper="3.14" velocity="1.571"/>
  </joint>
  <link name="plate_bottom_link">
    <visual>
      <origin rpy="0 0 0" xyz="0 0 0"/>
      <geometry>
        <mesh filename="package://turtlebot_description/meshes/stacks/hexagons/plate_bottom.dae"/>
      </geometry>
    </visual>
    <collision>
      <origin rpy="0 0 0" xyz="-0.02364 0 0"/>
      <geometry>
        <cylinder length="0.006" radius="0.170"/>
      </geometry>
    </collision>
    <inertial>
      <mass value="0.520"/>
      <origin xyz="0 0 0"/>
      <inertia ixx="0.003328" ixy="0.0" ixz="0.0" iyy="0.003328" iyz="0.0" izz="0.006656"/>
    </inertial>
  </link>
  <joint name="pole_middle_0_joint" type="fixed">
    <origin rpy="0 0 0" xyz="0.0381 0.1505 0.164"/>
    <parent link="base_link"/>
    <child link="pole_middle_0_link"/>
    <origin rpy="0 0 0" xyz="0.13525 0.0 0.034"/>
    <axis xyz="0 0 1"/>
    <limit effort="30" lower="-3.14" upper="3.14" velocity="1.571"/>
  </joint>
  <link name="pole_middle_0_link">
    <visual>
      <origin rpy="0 3.14159265359 0" xyz="0 0 0"/>
      <geometry>
        <mesh filename="package://turtlebot_description/meshes/stacks/hexagons/pole_middle.dae"/>
      </geometry>
    </visual>
    <collision>
      <origin rpy="0 0 0" xyz="0 0 0"/>
      <geometry>
        <cylinder length="0.0608" radius="0.006"/>
      </geometry>
    </collision>
    <inertial>
      <mass value="0.012"/>
      <origin xyz="0 0 0"/>
      <inertia ixx="0.000003805" ixy="0.0" ixz="0.0" iyy="0.000003805" iyz="0.0" izz="0.000000216"/>
    </inertial>
  </link>
  <joint name="pole_middle_1_joint" type="fixed">
    <origin rpy="0 0 0" xyz="0.0381 -0.1505 0.164"/>
    <parent link="base_link"/>
    <child link="pole_middle_1_link"/>
    <origin rpy="0 0 0" xyz="0.13525 0.0 0.034"/>
    <axis xyz="0 0 1"/>
    <limit effort="30" lower="-3.14" upper="3.14" velocity="1.571"/>
  </joint>
  <link name="pole_middle_1_link">
    <visual>
      <origin rpy="0 3.14159265359 0" xyz="0 0 0"/>
      <geometry>
        <mesh filename="package://turtlebot_description/meshes/stacks/hexagons/pole_middle.dae"/>
      </geometry>
    </visual>
    <collision>
      <origin rpy="0 0 0" xyz="0 0 0"/>
      <geometry>
        <cylinder length="0.0608" radius="0.006"/>
      </geometry>
    </collision>
    <inertial>
      <mass value="0.012"/>
      <origin xyz="0 0 0"/>
      <inertia ixx="0.000003805" ixy="0.0" ixz="0.0" iyy="0.000003805" iyz="0.0" izz="0.000000216"/>
    </inertial>
  </link>
  <joint name="pole_middle_2_joint" type="fixed">
    <origin rpy="0 0 0" xyz="-0.0381 0.1505 0.164"/>
    <parent link="base_link"/>
    <child link="pole_middle_2_link"/>
    <origin rpy="0 0 0" xyz="0.13525 0.0 0.034"/>
    <axis xyz="0 0 1"/>
    <limit effort="30" lower="-3.14" upper="3.14" velocity="1.571"/>
  </joint>
  <link name="pole_middle_2_link">
    <visual>
      <origin rpy="0 3.14159265359 0" xyz="0 0 0"/>
      <geometry>
        <mesh filename="package://turtlebot_description/meshes/stacks/hexagons/pole_middle.dae"/>
      </geometry>
    </visual>
    <collision>
      <origin rpy="0 0 0" xyz="0 0 0"/>
      <geometry>
        <cylinder length="0.0608" radius="0.006"/>
      </geometry>
    </collision>
    <inertial>
      <mass value="0.012"/>
      <origin xyz="0 0 0"/>
      <inertia ixx="0.000003805" ixy="0.0" ixz="0.0" iyy="0.000003805" iyz="0.0" izz="0.000000216"/>
    </inertial>
  </link>
  <joint name="pole_middle_3_joint" type="fixed">
    <origin rpy="0 0 0" xyz="-0.0381 -0.1505 0.164"/>
    <parent link="base_link"/>
    <child link="pole_middle_3_link"/>
    <origin rpy="0 0 0" xyz="0.13525 0.0 0.034"/>
    <axis xyz="0 0 1"/>
    <limit effort="30" lower="-3.14" upper="3.14" velocity="1.571"/>
  </joint>
  <link name="pole_middle_3_link">
    <visual>
      <origin rpy="0 3.14159265359 0" xyz="0 0 0"/>
      <geometry>
        <mesh filename="package://turtlebot_description/meshes/stacks/hexagons/pole_middle.dae"/>
      </geometry>
    </visual>
    <collision>
      <origin rpy="0 0 0" xyz="0 0 0"/>
      <geometry>
        <cylinder length="0.0608" radius="0.006"/>
      </geometry>
    </collision>
    <inertial>
      <mass value="0.012"/>
      <origin xyz="0 0 0"/>
      <inertia ixx="0.000003805" ixy="0.0" ixz="0.0" iyy="0.000003805" iyz="0.0" izz="0.000000216"/>
    </inertial>
  </link>
  <!-- cchange plate_middle_joint Z-->
  <joint name="plate_middle_joint" type="fixed">
    <origin rpy="0 0 0" xyz="-0.01364 0.0 0.2264"/>
    <parent link="base_link"/>
    <child link="plate_middle_link"/>
    <origin rpy="0 0 0" xyz="0.13525 0.0 0.034"/>
    <axis xyz="0 0 1"/>
    <limit effort="30" lower="-3.14" upper="3.14" velocity="1.571"/>
  </joint>
  <link name="plate_middle_link">
    <visual>
      <origin rpy="0 0 0" xyz="0 0 0.0"/>
      <geometry>
        <mesh filename="package://turtlebot_description/meshes/stacks/hexagons/plate_middle.dae"/>
      </geometry>
    </visual>
    <collision>
      <origin rpy="0 0 0" xyz="0.01364 0.0 0.0"/>
      <geometry>
        <cylinder length="0.006" radius="0.170"/>
      </geometry>
    </collision>
    <inertial>
      <mass value="0.520"/>
      <origin xyz="0 0 0"/>
      <inertia ixx="0.003328" ixy="0.0" ixz="0.0" iyy="0.003328" iyz="0.0" izz="0.006656"/>
    </inertial>
  </link>
  <joint name="pole_top_0_joint" type="fixed">
    <origin rpy="0 0 0" xyz="0.0381 0.1505 0.3312"/>
    <parent link="base_link"/>
    <child link="pole_top_0_link"/>
    <origin rpy="0 0 0" xyz="0.13525 0.0 0.034"/>
    <axis xyz="0 0 1"/>
    <limit effort="30" lower="-3.14" upper="3.14" velocity="1.571"/>
  </joint>
  <link name="pole_top_0_link">
    <visual>
      <origin rpy="0 0 0" xyz=" 0 0 0"/>
      <geometry>
        <mesh filename="package://turtlebot_description/meshes/stacks/hexagons/pole_top.dae"/>
      </geometry>
    </visual>
    <collision>
      <origin rpy="0 0 0" xyz="0 0 0"/>
      <geometry>
        <cylinder length="0.2032" radius="0.006"/>
      </geometry>
    </collision>
    <inertial>
      <mass value="0.060"/>
      <origin xyz="0 0 0"/>
      <inertia ixx="0.000206991" ixy="0.0" ixz="0.0" iyy="0.000206991" iyz="0.0" izz="0.000001080"/>
    </inertial>
  </link>
  <joint name="pole_top_1_joint" type="fixed">
    <origin rpy="0 0 0" xyz="0.0381 -0.1505 0.3312"/>
    <parent link="base_link"/>
    <child link="pole_top_1_link"/>
    <origin rpy="0 0 0" xyz="0.13525 0.0 0.034"/>
    <axis xyz="0 0 1"/>
    <limit effort="30" lower="-3.14" upper="3.14" velocity="1.571"/>
  </joint>
  <link name="pole_top_1_link">
    <visual>
      <origin rpy="0 0 0" xyz=" 0 0 0"/>
      <geometry>
        <mesh filename="package://turtlebot_description/meshes/stacks/hexagons/pole_top.dae"/>
      </geometry>
    </visual>
    <collision>
      <origin rpy="0 0 0" xyz="0 0 0"/>
      <geometry>
        <cylinder length="0.2032" radius="0.006"/>
      </geometry>
    </collision>
    <inertial>
      <mass value="0.060"/>
      <origin xyz="0 0 0"/>
      <inertia ixx="0.000206991" ixy="0.0" ixz="0.0" iyy="0.000206991" iyz="0.0" izz="0.000001080"/>
    </inertial>
  </link>
  <joint name="pole_top_2_joint" type="fixed">
    <origin rpy="0 0 0" xyz="-0.0381 0.1505 0.3312"/>
    <parent link="base_link"/>
    <child link="pole_top_2_link"/>
    <origin rpy="0 0 0" xyz="0.13525 0.0 0.034"/>
    <axis xyz="0 0 1"/>
    <limit effort="30" lower="-3.14" upper="3.14" velocity="1.571"/>
  </joint>
  <link name="pole_top_2_link">
    <visual>
      <origin rpy="0 0 0" xyz=" 0 0 0"/>
      <geometry>
        <mesh filename="package://turtlebot_description/meshes/stacks/hexagons/pole_top.dae"/>
      </geometry>
    </visual>
    <collision>
      <origin rpy="0 0 0" xyz="0 0 0"/>
      <geometry>
        <cylinder length="0.2032" radius="0.006"/>
      </geometry>
    </collision>
    <inertial>
      <mass value="0.060"/>
      <origin xyz="0 0 0"/>
      <inertia ixx="0.000206991" ixy="0.0" ixz="0.0" iyy="0.000206991" iyz="0.0" izz="0.000001080"/>
    </inertial>
  </link>
  <joint name="pole_top_3_joint" type="fixed">
    <origin rpy="0 0 0" xyz="-0.0381 -0.1505 0.3312"/>
    <parent link="base_link"/>
    <child link="pole_top_3_link"/>
    <origin rpy="0 0 0" xyz="0.13525 0.0 0.034"/>
    <axis xyz="0 0 1"/>
    <limit effort="30" lower="-3.14" upper="3.14" velocity="1.571"/>
  </joint>
  <link name="pole_top_3_link">
    <visual>
      <origin rpy="0 0 0" xyz=" 0 0 0"/>
      <geometry>
        <mesh filename="package://turtlebot_description/meshes/stacks/hexagons/pole_top.dae"/>
      </geometry>
    </visual>
    <collision>
      <origin rpy="0 0 0" xyz="0 0 0"/>
      <geometry>
        <cylinder length="0.2032" radius="0.006"/>
      </geometry>
    </collision>
    <inertial>
      <mass value="0.060"/>
      <origin xyz="0 0 0"/>
      <inertia ixx="0.000206991" ixy="0.0" ixz="0.0" iyy="0.000206991" iyz="0.0" izz="0.000001080"/>
    </inertial>
  </link>
  <stack_3d_sensor_pole number="0" parent="base_link" x_loc="-0.1024" y_loc="0.098" z_loc="0.2372"/>
  <stack_3d_sensor_pole number="1" parent="base_link" x_loc="-0.1024" y_loc="-0.098" z_loc="0.2372"/>
  <!-- cchange plate_top_joint Z-->
  <joint name="plate_top_joint" type="fixed">
    <origin rpy="0 0 0" xyz="-0.01364 0.0  0.4356"/>
    <parent link="base_link"/>
    <child link="plate_top_link"/>
    <origin rpy="0 0 0" xyz="0.13525 0.0 0.034"/>
    <axis xyz="0 0 1"/>
    <limit effort="30" lower="-3.14" upper="3.14" velocity="1.571"/>
  </joint>
  <link name="plate_top_link">
    <visual>
      <origin rpy="0 0 0" xyz="0 0 0.0"/>
      <geometry>
        <mesh filename="package://turtlebot_description/meshes/stacks/hexagons/plate_top.dae"/>
      </geometry>
    </visual>
    <collision>
      <origin rpy="0 0 0" xyz="0.01364 0 0.0"/>
      <geometry>
        <cylinder length="0.006" radius="0.170"/>
      </geometry>
    </collision>
    <inertial>
      <mass value="0.520"/>
      <origin xyz="0 0 0"/>
      <inertia ixx="0.003328" ixy="0.0" ixz="0.0" iyy="0.003328" iyz="0.0" izz="0.006656"/>
    </inertial>
  </link>
  <sensor_asus_xtion_pro parent="base_link"/>
</robot>

